Workbook

Sheet 📋 Instructions
B2: XXX - CONTRACT BURN RATE TRACKER
B3: PoP: 24 Feb 2025 – 23 Feb 2026 | Prime: xxxxxx
B5: WORKBOOK STRUCTURE
B6: ⚙️ Setup | C6: Enter contract metadata, CLIN ceiling & funded values. This is the master reference for all other sheets.
B7: 📝 Mod Tracker | C7: Log every contract modification (P00001, P00002…). Each mod updates ceiling/funding and the history is preserved.
B8: 📅 Monthly Tabs | C8: 13 monthly tabs (Feb partial → Feb partial). Enter Prime Actuals, Sub Actuals, and Forecast per CLIN each month.
B9: 📊 Burn Summary | C9: Auto-calculated YTD roll-up: KPI banner, monthly table, CLIN-level summary, status flags, % burned.
B10: 📈 CLIN Charts | C10: One burn chart per CLIN showing Ceiling, Funding, Actuals, and Actuals+Forecast projected to contract end.
B11: COLOR LEGEND
B12: Blue text / blue bg | C12: Input cell — enter your data here
B13: Black text / gray bg | C13: Formula / auto-calculated — do not overwrite
B14: Green text | C14: Cross-sheet link — auto-populated from another tab
B15: Yellow background | C15: Key assumption — review before use
B16: ⚠️ NEAR LIMIT (red) | C16: Cumulative burn ≥ 95% of funded amount
B17: 🟡 CAUTION (amber) | C17: Cumulative burn ≥ 80% of funded amount
B18: ✅ ON TRACK (green) | C18: Cumulative burn < 80% of funded amount

Sheet ⚙️ Setup
B2: CONTRACT SETUP & CLIN MASTER
B4: CONTRACT METADATA
B5: Contract Number
B6: Program
B7: Prime
B8: Primary Client
B9: Secondary Client
B10: PoP Start
B11: PoP End
B12: PM
B13: CLIN MASTER — CURRENT VALUES (Updated by Mod Tracker)
B14: CLIN | C14: Description | D14: Type | E14: Current Ceiling ($) | F14: Current Funded ($) | G14: Sub? | H14: Notes
B15: 1005 | C15: Project Management | D15: FFP | E15: ='📝 Mod Tracker'!J106 -> 593717.36 | F15: ='📝 Mod Tracker'!J107 -> 432918.91 | G15: No
B16: 1006 | C16: Software Maintenance | D16: CPFF | E16: ='📝 Mod Tracker'!N106 -> 727970.79 | F16: ='📝 Mod Tracker'!N107 -> 561144.15 | G16: No
B17: 1007 | C17: Software Development | D17: CPFF | E17: ='📝 Mod Tracker'!R106 -> 869923.61 | F17: ='📝 Mod Tracker'!R107 -> 670566.12 | G17: No
B18: 1008 | C18: O&M | D18: CPFF | E18: ='📝 Mod Tracker'!V106 -> 688014.82 | F18: ='📝 Mod Tracker'!V107 -> 501677.47 | G18: No
B19: 1009 | C19: Tier 3 Helpdesk | D19: FFP | E19: ='📝 Mod Tracker'!Z106 -> 33772.5 | F19: ='📝 Mod Tracker'!Z107 -> 24625.78 | G19: No
B20: 1010 | C20: Training | D20: FFP | E20: ='📝 Mod Tracker'!AD106 -> 199225.6 | F20: ='📝 Mod Tracker'!AD107 -> 145268.67 | G20: No
B21: 1016 | C21: NTIA | D21: FFP | E21: ='📝 Mod Tracker'!AH106 -> 268485.99 | F21: ='📝 Mod Tracker'!AH107 -> 268485.99 | G21: No
B22: 1017 | C22: Other Direct Costs | D22: COST | E22: ='📝 Mod Tracker'!AL106 -> 132000 | F22: ='📝 Mod Tracker'!AL107 -> 60486.24 | G22: No
B23: 1018 | C23: Travel | D23: COST | E23: ='📝 Mod Tracker'!AT106 -> 10144 | F23: ='📝 Mod Tracker'!AT107 -> 4999.99 | G23: No
B24: TOTAL | E24: =SUM(E15:E23) -> 3523254.7 | F24: =SUM(F15:F23) -> 2670173.3

Sheet 📝 Mod Tracker
B1: 📝 CONTRACT MODIFICATION TRACKER — PRIME
B2: FROM BY TO format: enter FROM (prior value) and BY (change delta). TO = FROM + BY (auto-calculated). FROM auto-fills from prior MOD's TO. MOD TYPES: Funding ▪ Scope ▪ Admin ▪ Clause/Language ▪ Mixed
B3: FROM BY TO LOGIC: "This MOD is increased FROM $500,000 BY $100,000 TO $600,000" | FROM auto-populates from prior MOD's TO · BY = your delta input (blue) · TO = FROM + BY (auto)
B4: Modification Details | H4: CLIN 1005 — Proj. Mgmt (FFP) | L4: CLIN 1006 — SW Maint. (CPFF) | P4: CLIN 1007 — SW Dev. (CPFF) | T4: CLIN 1008 — O&M (CPFF) | X4: CLIN 1009 — Tier 3 Help (FFP) | AB4: CLIN 1010 — Training (FFP) | AF4: CLIN 1016 — NTIA (FFP) | AJ4: CLIN 1017 — ODCs (COST) | AN4: CLIN 1018 — Travel (COST) | AR4: CLIN 1018 — Travel (COST) | AV4: CONTRACT TOTAL (All CLINs)
B5: MOD # | C5: Eff. Date | D5: MOD Type | E5: Description / What This MOD Changes | G5: Row | H5: FROM ($) | I5: BY ($) | J5: TO ($) | L5: FROM ($) | M5: BY ($) | N5: TO ($) | P5: FROM ($) | Q5: BY ($) | R5: TO ($) | T5: FROM ($) | U5: BY ($) | V5: TO ($) | X5: FROM ($) | Y5: BY ($) | Z5: TO ($) | AB5: FROM ($) | AC5: BY ($) | AD5: TO ($) | AF5: FROM ($) | AG5: BY ($) | AH5: TO ($) | AJ5: FROM ($) | AK5: BY ($) | AL5: TO ($) | AN5: FROM ($) | AO5: BY ($) | AP5: TO ($) | AR5: FROM ($) | AS5: BY ($) | AT5: TO ($) | AV5: FROM ($) | AW5: BY ($) | AX5: TO ($)
B7: AWARD (Baseline) | E7: Contract award — original baseline values. Enter award ceiling and funding amounts. | G7: CEILING | H7: N/A | I7: 0 | J7: =I7 -> 0 | L7: N/A | M7: 0 | N7: =M7 -> 0 | P7: N/A | Q7: 0 | R7: =Q7 -> 0 | T7: N/A | U7: 0 | V7: =U7 -> 0 | X7: N/A | Y7: 0 | Z7: =Y7 -> 0 | AB7: N/A | AC7: 0 | AD7: =AC7 -> 0 | AF7: N/A | AG7: 0 | AH7: =AG7 -> 0 | AJ7: N/A | AK7: 0 | AL7: =AK7 -> 0 | AN7: N/A | AO7: 0 | AP7: =AO7 -> 0 | AR7: N/A | AS7: 0 | AT7: =AS7 -> 0 | AV7: N/A | AW7: =I7+M7+Q7+U7+Y7+AC7+AG7+AK7+AS7 -> 0 | AX7: =J7+N7+R7+V7+Z7+AD7+AH7+AL7+AT7 -> 0
G8: FUNDING | H8: N/A | I8: 0 | J8: =I8 -> 0 | L8: N/A | M8: 0 | N8: =M8 -> 0 | P8: N/A | Q8: 0 | R8: =Q8 -> 0 | T8: N/A | U8: 0 | V8: =U8 -> 0 | X8: N/A | Y8: 0 | Z8: =Y8 -> 0 | AB8: N/A | AC8: 0 | AD8: =AC8 -> 0 | AF8: N/A | AG8: 0 | AH8: =AG8 -> 0 | AJ8: N/A | AK8: 0 | AL8: =AK8 -> 0 | AN8: N/A | AO8: 0 | AP8: =AO8 -> 0 | AR8: N/A | AS8: 0 | AT8: =AS8 -> 0 | AV8: N/A | AW8: =I8+M8+Q8+U8+Y8+AC8+AG8+AK8+AS8 -> 0 | AX8: =J8+N8+R8+V8+Z8+AD8+AH8+AL8+AT8 -> 0
B10: P00001 | G10: CEILING | H10: =J7 -> 0 | I10: 0 | J10: =H10+I10 -> 0 | L10: =N7 -> 0 | M10: 0 | N10: =L10+M10 -> 0 | P10: =R7 -> 0 | Q10: 0 | R10: =P10+Q10 -> 0 | T10: =V7 -> 0 | U10: 0 | V10: =T10+U10 -> 0 | X10: =Z7 -> 0 | Y10: 0 | Z10: =X10+Y10 -> 0 | AB10: =AD7 -> 0 | AC10: 0 | AD10: =AB10+AC10 -> 0 | AF10: =AH7 -> 0 | AG10: 0 | AH10: =AF10+AG10 -> 0 | AJ10: =AL7 -> 0 | AK10: 0 | AL10: =AJ10+AK10 -> 0 | AN10: =AP7 -> 0 | AO10: 0 | AP10: =AN10+AO10 -> 0 | AR10: =AT7 -> 0 | AS10: 0 | AT10: =AR10+AS10 -> 0 | AV10: =H10+L10+P10+T10+X10+AB10+AF10+AJ10+AR10 -> 0 | AW10: =I10+M10+Q10+U10+Y10+AC10+AG10+AK10+AS10 -> 0 | AX10: =J10+N10+R10+V10+Z10+AD10+AH10+AL10+AT10 -> 0
G11: FUNDING | H11: =J8 -> 0 | I11: 0 | J11: =H11+I11 -> 0 | L11: =N8 -> 0 | M11: 0 | N11: =L11+M11 -> 0 | P11: =R8 -> 0 | Q11: 0 | R11: =P11+Q11 -> 0 | T11: =V8 -> 0 | U11: 0 | V11: =T11+U11 -> 0 | X11: =Z8 -> 0 | Y11: 0 | Z11: =X11+Y11 -> 0 | AB11: =AD8 -> 0 | AC11: 0 | AD11: =AB11+AC11 -> 0 | AF11: =AH8 -> 0 | AG11: 0 | AH11: =AF11+AG11 -> 0 | AJ11: =AL8 -> 0 | AK11: 0 | AL11: =AJ11+AK11 -> 0 | AN11: =AP8 -> 0 | AO11: 0 | AP11: =AN11+AO11 -> 0 | AR11: =AT8 -> 0 | AS11: 0 | AT11: =AR11+AS11 -> 0 | AV11: =H11+L11+P11+T11+X11+AB11+AF11+AJ11+AR11 -> 0 | AW11: =I11+M11+Q11+U11+Y11+AC11+AG11+AK11+AS11 -> 0 | AX11: =J11+N11+R11+V11+Z11+AD11+AH11+AL11+AT11 -> 0
B12: 📋 MOD SNAPSHOT — What does this modification do? (enter description: funding increase, scope change, new clause, administrative, etc.)
B14: P00002 | G14: CEILING | H14: =J10 -> 0 | I14: 0 | J14: =H14+I14 -> 0 | L14: =N10 -> 0 | M14: 0 | N14: =L14+M14 -> 0 | P14: =R10 -> 0 | Q14: 0 | R14: =P14+Q14 -> 0 | T14: =V10 -> 0 | U14: 0 | V14: =T14+U14 -> 0 | X14: =Z10 -> 0 | Y14: 0 | Z14: =X14+Y14 -> 0 | AB14: =AD10 -> 0 | AC14: 0 | AD14: =AB14+AC14 -> 0 | AF14: =AH10 -> 0 | AG14: 0 | AH14: =AF14+AG14 -> 0 | AJ14: =AL10 -> 0 | AK14: 0 | AL14: =AJ14+AK14 -> 0 | AN14: =AP10 -> 0 | AO14: 0 | AP14: =AN14+AO14 -> 0 | AR14: =AT10 -> 0 | AS14: 0 | AT14: =AR14+AS14 -> 0 | AV14: =H14+L14+P14+T14+X14+AB14+AF14+AJ14+AR14 -> 0 | AW14: =I14+M14+Q14+U14+Y14+AC14+AG14+AK14+AS14 -> 0 | AX14: =J14+N14+R14+V14+Z14+AD14+AH14+AL14+AT14 -> 0
G15: FUNDING | H15: =J11 -> 0 | I15: 0 | J15: =H15+I15 -> 0 | L15: =N11 -> 0 | M15: 0 | N15: =L15+M15 -> 0 | P15: =R11 -> 0 | Q15: 0 | R15: =P15+Q15 -> 0 | T15: =V11 -> 0 | U15: 0 | V15: =T15+U15 -> 0 | X15: =Z11 -> 0 | Y15: 0 | Z15: =X15+Y15 -> 0 | AB15: =AD11 -> 0 | AC15: 0 | AD15: =AB15+AC15 -> 0 | AF15: =AH11 -> 0 | AG15: 0 | AH15: =AF15+AG15 -> 0 | AJ15: =AL11 -> 0 | AK15: 0 | AL15: =AJ15+AK15 -> 0 | AN15: =AP11 -> 0 | AO15: 0 | AP15: =AN15+AO15 -> 0 | AR15: =AT11 -> 0 | AS15: 0 | AT15: =AR15+AS15 -> 0 | AV15: =H15+L15+P15+T15+X15+AB15+AF15+AJ15+AR15 -> 0 | AW15: =I15+M15+Q15+U15+Y15+AC15+AG15+AK15+AS15 -> 0 | AX15: =J15+N15+R15+V15+Z15+AD15+AH15+AL15+AT15 -> 0
B16: 📋 MOD SNAPSHOT — What does this modification do? (enter description: funding increase, scope change, new clause, administrative, etc.)
B18: P00003 | G18: CEILING | H18: =J14 -> 0 | I18: 0 | J18: =H18+I18 -> 0 | L18: =N14 -> 0 | M18: 0 | N18: =L18+M18 -> 0 | P18: =R14 -> 0 | Q18: 0 | R18: =P18+Q18 -> 0 | T18: =V14 -> 0 | U18: 0 | V18: =T18+U18 -> 0 | X18: =Z14 -> 0 | Y18: 0 | Z18: =X18+Y18 -> 0 | AB18: =AD14 -> 0 | AC18: 0 | AD18: =AB18+AC18 -> 0 | AF18: =AH14 -> 0 | AG18: 0 | AH18: =AF18+AG18 -> 0 | AJ18: =AL14 -> 0 | AK18: 0 | AL18: =AJ18+AK18 -> 0 | AN18: =AP14 -> 0 | AO18: 0 | AP18: =AN18+AO18 -> 0 | AR18: =AT14 -> 0 | AS18: 0 | AT18: =AR18+AS18 -> 0 | AV18: =H18+L18+P18+T18+X18+AB18+AF18+AJ18+AR18 -> 0 | AW18: =I18+M18+Q18+U18+Y18+AC18+AG18+AK18+AS18 -> 0 | AX18: =J18+N18+R18+V18+Z18+AD18+AH18+AL18+AT18 -> 0
G19: FUNDING | H19: =J15 -> 0 | I19: 0 | J19: =H19+I19 -> 0 | L19: =N15 -> 0 | M19: 0 | N19: =L19+M19 -> 0 | P19: =R15 -> 0 | Q19: 0 | R19: =P19+Q19 -> 0 | T19: =V15 -> 0 | U19: 0 | V19: =T19+U19 -> 0 | X19: =Z15 -> 0 | Y19: 0 | Z19: =X19+Y19 -> 0 | AB19: =AD15 -> 0 | AC19: 0 | AD19: =AB19+AC19 -> 0 | AF19: =AH15 -> 0 | AG19: 0 | AH19: =AF19+AG19 -> 0 | AJ19: =AL15 -> 0 | AK19: 0 | AL19: =AJ19+AK19 -> 0 | AN19: =AP15 -> 0 | AO19: 0 | AP19: =AN19+AO19 -> 0 | AR19: =AT15 -> 0 | AS19: 0 | AT19: =AR19+AS19 -> 0 | AV19: =H19+L19+P19+T19+X19+AB19+AF19+AJ19+AR19 -> 0 | AW19: =I19+M19+Q19+U19+Y19+AC19+AG19+AK19+AS19 -> 0 | AX19: =J19+N19+R19+V19+Z19+AD19+AH19+AL19+AT19 -> 0
B20: 📋 MOD SNAPSHOT — What does this modification do? (enter description: funding increase, scope change, new clause, administrative, etc.)
B22: P00004 | G22: CEILING | H22: =J18 -> 0 | I22: 0 | J22: =H22+I22 -> 0 | L22: =N18 -> 0 | M22: 0 | N22: =L22+M22 -> 0 | P22: =R18 -> 0 | Q22: 0 | R22: =P22+Q22 -> 0 | T22: =V18 -> 0 | U22: 0 | V22: =T22+U22 -> 0 | X22: =Z18 -> 0 | Y22: 0 | Z22: =X22+Y22 -> 0 | AB22: =AD18 -> 0 | AC22: 0 | AD22: =AB22+AC22 -> 0 | AF22: =AH18 -> 0 | AG22: 0 | AH22: =AF22+AG22 -> 0 | AJ22: =AL18 -> 0 | AK22: 0 | AL22: =AJ22+AK22 -> 0 | AN22: =AP18 -> 0 | AO22: 0 | AP22: =AN22+AO22 -> 0 | AR22: =AT18 -> 0 | AS22: 0 | AT22: =AR22+AS22 -> 0 | AV22: =H22+L22+P22+T22+X22+AB22+AF22+AJ22+AR22 -> 0 | AW22: =I22+M22+Q22+U22+Y22+AC22+AG22+AK22+AS22 -> 0 | AX22: =J22+N22+R22+V22+Z22+AD22+AH22+AL22+AT22 -> 0
G23: FUNDING | H23: =J19 -> 0 | I23: 0 | J23: =H23+I23 -> 0 | L23: =N19 -> 0 | M23: 0 | N23: =L23+M23 -> 0 | P23: =R19 -> 0 | Q23: 0 | R23: =P23+Q23 -> 0 | T23: =V19 -> 0 | U23: 0 | V23: =T23+U23 -> 0 | X23: =Z19 -> 0 | Y23: 0 | Z23: =X23+Y23 -> 0 | AB23: =AD19 -> 0 | AC23: 0 | AD23: =AB23+AC23 -> 0 | AF23: =AH19 -> 0 | AG23: 0 | AH23: =AF23+AG23 -> 0 | AJ23: =AL19 -> 0 | AK23: 0 | AL23: =AJ23+AK23 -> 0 | AN23: =AP19 -> 0 | AO23: 0 | AP23: =AN23+AO23 -> 0 | AR23: =AT19 -> 0 | AS23: 0 | AT23: =AR23+AS23 -> 0 | AV23: =H23+L23+P23+T23+X23+AB23+AF23+AJ23+AR23 -> 0 | AW23: =I23+M23+Q23+U23+Y23+AC23+AG23+AK23+AS23 -> 0 | AX23: =J23+N23+R23+V23+Z23+AD23+AH23+AL23+AT23 -> 0
B24: 📋 MOD SNAPSHOT — What does this modification do? (enter description: funding increase, scope change, new clause, administrative, etc.)
B26: P00005 | G26: CEILING | H26: =J22 -> 0 | I26: 0 | J26: =H26+I26 -> 0 | L26: =N22 -> 0 | M26: 0 | N26: =L26+M26 -> 0 | P26: =R22 -> 0 | Q26: 0 | R26: =P26+Q26 -> 0 | T26: =V22 -> 0 | U26: 0 | V26: =T26+U26 -> 0 | X26: =Z22 -> 0 | Y26: 0 | Z26: =X26+Y26 -> 0 | AB26: =AD22 -> 0 | AC26: 0 | AD26: =AB26+AC26 -> 0 | AF26: =AH22 -> 0 | AG26: 0 | AH26: =AF26+AG26 -> 0 | AJ26: =AL22 -> 0 | AK26: 0 | AL26: =AJ26+AK26 -> 0 | AN26: =AP22 -> 0 | AO26: 0 | AP26: =AN26+AO26 -> 0 | AR26: =AT22 -> 0 | AS26: 0 | AT26: =AR26+AS26 -> 0 | AV26: =H26+L26+P26+T26+X26+AB26+AF26+AJ26+AR26 -> 0 | AW26: =I26+M26+Q26+U26+Y26+AC26+AG26+AK26+AS26 -> 0 | AX26: =J26+N26+R26+V26+Z26+AD26+AH26+AL26+AT26 -> 0
G27: FUNDING | H27: =J23 -> 0 | I27: 0 | J27: =H27+I27 -> 0 | L27: =N23 -> 0 | M27: 0 | N27: =L27+M27 -> 0 | P27: =R23 -> 0 | Q27: 0 | R27: =P27+Q27 -> 0 | T27: =V23 -> 0 | U27: 0 | V27: =T27+U27 -> 0 | X27: =Z23 -> 0 | Y27: 0 | Z27: =X27+Y27 -> 0 | AB27: =AD23 -> 0 | AC27: 0 | AD27: =AB27+AC27 -> 0 | AF27: =AH23 -> 0 | AG27: 0 | AH27: =AF27+AG27 -> 0 | AJ27: =AL23 -> 0 | AK27: 0 | AL27: =AJ27+AK27 -> 0 | AN27: =AP23 -> 0 | AO27: 0 | AP27: =AN27+AO27 -> 0 | AR27: =AT23 -> 0 | AS27: 0 | AT27: =AR27+AS27 -> 0 | AV27: =H27+L27+P27+T27+X27+AB27+AF27+AJ27+AR27 -> 0 | AW27: =I27+M27+Q27+U27+Y27+AC27+AG27+AK27+AS27 -> 0 | AX27: =J27+N27+R27+V27+Z27+AD27+AH27+AL27+AT27 -> 0
B28: 📋 MOD SNAPSHOT — What does this modification do? (enter description: funding increase, scope change, new clause, administrative, etc.)
B30: P00006 | G30: CEILING | H30: =J26 -> 0 | I30: 0 | J30: =H30+I30 -> 0 | L30: =N26 -> 0 | M30: 0 | N30: =L30+M30 -> 0 | P30: =R26 -> 0 | Q30: 0 | R30: =P30+Q30 -> 0 | T30: =V26 -> 0 | U30: 0 | V30: =T30+U30 -> 0 | X30: =Z26 -> 0 | Y30: 0 | Z30: =X30+Y30 -> 0 | AB30: =AD26 -> 0 | AC30: 0 | AD30: =AB30+AC30 -> 0 | AF30: =AH26 -> 0 | AG30: 0 | AH30: =AF30+AG30 -> 0 | AJ30: =AL26 -> 0 | AK30: 0 | AL30: =AJ30+AK30 -> 0 | AN30: =AP26 -> 0 | AO30: 0 | AP30: =AN30+AO30 -> 0 | AR30: =AT26 -> 0 | AS30: 0 | AT30: =AR30+AS30 -> 0 | AV30: =H30+L30+P30+T30+X30+AB30+AF30+AJ30+AR30 -> 0 | AW30: =I30+M30+Q30+U30+Y30+AC30+AG30+AK30+AS30 -> 0 | AX30: =J30+N30+R30+V30+Z30+AD30+AH30+AL30+AT30 -> 0
G31: FUNDING | H31: =J27 -> 0 | I31: 0 | J31: =H31+I31 -> 0 | L31: =N27 -> 0 | M31: 0 | N31: =L31+M31 -> 0 | P31: =R27 -> 0 | Q31: 0 | R31: =P31+Q31 -> 0 | T31: =V27 -> 0 | U31: 0 | V31: =T31+U31 -> 0 | X31: =Z27 -> 0 | Y31: 0 | Z31: =X31+Y31 -> 0 | AB31: =AD27 -> 0 | AC31: 0 | AD31: =AB31+AC31 -> 0 | AF31: =AH27 -> 0 | AG31: 0 | AH31: =AF31+AG31 -> 0 | AJ31: =AL27 -> 0 | AK31: 0 | AL31: =AJ31+AK31 -> 0 | AN31: =AP27 -> 0 | AO31: 0 | AP31: =AN31+AO31 -> 0 | AR31: =AT27 -> 0 | AS31: 0 | AT31: =AR31+AS31 -> 0 | AV31: =H31+L31+P31+T31+X31+AB31+AF31+AJ31+AR31 -> 0 | AW31: =I31+M31+Q31+U31+Y31+AC31+AG31+AK31+AS31 -> 0 | AX31: =J31+N31+R31+V31+Z31+AD31+AH31+AL31+AT31 -> 0
B32: 📋 MOD SNAPSHOT — What does this modification do? (enter description: funding increase, scope change, new clause, administrative, etc.)
B34: P00007 | D34: Mixed | E34: • Incorporate DFARS 252.204-7021 • Incorporate revised PWS (Removal of v5 vs v6 nomenclature) • Provide BY funding in amount of $153,073.42 | G34: CEILING | H34: =J30 -> 0 | I34: 0 | J34: =H34+I34 -> 0 | L34: =N30 -> 0 | M34: 0 | N34: =L34+M34 -> 0 | P34: =R30 -> 0 | Q34: 0 | R34: =P34+Q34 -> 0 | T34: =V30 -> 0 | U34: 0 | V34: =T34+U34 -> 0 | X34: =Z30 -> 0 | Y34: 0 | Z34: =X34+Y34 -> 0 | AB34: =AD30 -> 0 | AC34: 0 | AD34: =AB34+AC34 -> 0 | AF34: =AH30 -> 0 | AG34: 0 | AH34: =AF34+AG34 -> 0 | AJ34: =AL30 -> 0 | AK34: 0 | AL34: =AJ34+AK34 -> 0 | AN34: =AP30 -> 0 | AO34: 0 | AP34: =AN34+AO34 -> 0 | AR34: =AT30 -> 0 | AS34: 0 | AT34: =AR34+AS34 -> 0 | AV34: =H34+L34+P34+T34+X34+AB34+AF34+AJ34+AR34 -> 0 | AW34: =I34+M34+Q34+U34+Y34+AC34+AG34+AK34+AS34 -> 0 | AX34: =J34+N34+R34+V34+Z34+AD34+AH34+AL34+AT34 -> 0
G35: FUNDING | H35: =J31 -> 0 | I35: 0 | J35: =H35+I35 -> 0 | L35: =N31 -> 0 | M35: 0 | N35: =L35+M35 -> 0 | P35: =R31 -> 0 | R35: =P35+Q35 -> 0 | T35: =V31 -> 0 | U35: 0 | V35: =T35+U35 -> 0 | X35: =Z31 -> 0 | Y35: 0 | Z35: =X35+Y35 -> 0 | AB35: =AD31 -> 0 | AC35: 0 | AD35: =AB35+AC35 -> 0 | AF35: =AH31 -> 0 | AG35: 0 | AH35: =AF35+AG35 -> 0 | AJ35: =AL31 -> 0 | AK35: 0 | AL35: =AJ35+AK35 -> 0 | AN35: =AP31 -> 0 | AO35: 0 | AP35: =AN35+AO35 -> 0 | AR35: =AT31 -> 0 | AS35: 0 | AT35: =AR35+AS35 -> 0 | AV35: =H35+L35+P35+T35+X35+AB35+AF35+AJ35+AR35 -> 0 | AW35: =I35+M35+Q35+U35+Y35+AC35+AG35+AK35+AS35 -> 0 | AX35: =J35+N35+R35+V35+Z35+AD35+AH35+AL35+AT35 -> 0
B36: 📋 MOD SNAPSHOT — What does this modification do? (enter description: funding increase, scope change, new clause, administrative, etc.)
B38: P00008 | D38: Mixed | E38: • Realign ceiling and funding for BY CLIN 0017 & 0018 • Incorporate revisied 6.10 - Training PWS • Exercise OY1 • Provide OY1 funding | G38: CEILING | I38: 593717.36 | J38: =H38+I38 -> 593717.36 | L38: =N34 -> 0 | M38: 727970.79 | N38: =L38+M38 -> 727970.79 | P38: =R34 -> 0 | Q38: 869923.61 | R38: =P38+Q38 -> 869923.61 | T38: =V34 -> 0 | U38: 688014.82 | V38: =T38+U38 -> 688014.82 | X38: =Z34 -> 0 | Y38: 33772.5 | Z38: =X38+Y38 -> 33772.5 | AB38: =AD34 -> 0 | AC38: 199225.6 | AD38: =AB38+AC38 -> 199225.6 | AF38: =AH34 -> 0 | AG38: 268485.99 | AH38: =AF38+AG38 -> 268485.99 | AJ38: =AL34 -> 0 | AK38: 132000 | AL38: =AJ38+AK38 -> 132000 | AN38: =AP34 -> 0 | AO38: 10144 | AP38: =AN38+AO38 -> 10144 | AR38: =AT34 -> 0 | AS38: 10144 | AT38: =AR38+AS38 -> 10144 | AV38: =H38+L38+P38+T38+X38+AB38+AF38+AJ38+AR38 -> 0 | AW38: =I38+M38+Q38+U38+Y38+AC38+AG38+AK38+AS38 -> 3523254.7 | AX38: =J38+N38+R38+V38+Z38+AD38+AH38+AL38+AT38 -> 3523254.7
G39: FUNDING | H39: =J35 -> 0 | I39: 98952.89 | J39: =H39+I39 -> 98952.89 | L39: =N35 -> 0 | M39: 151660.58 | N39: =L39+M39 -> 151660.58 | P39: =R35 -> 0 | Q39: 181234.09 | R39: =P39+Q39 -> 181234.09 | T39: =V35 -> 0 | U39: 114669.14 | V39: =T39+U39 -> 114669.14 | X39: =Z35 -> 0 | Y39: 5628.75 | Z39: =X39+Y39 -> 5628.75 | AB39: =AD35 -> 0 | AC39: 33204.27 | AD39: =AB39+AC39 -> 33204.27 | AF39: =AH35 -> 0 | AG39: 268485.99 | AH39: =AF39+AG39 -> 268485.99 | AJ39: =AL35 -> 0 | AK39: 22000 | AL39: =AJ39+AK39 -> 22000 | AN39: =AP35 -> 0 | AO39: 1690.66 | AP39: =AN39+AO39 -> 1690.66 | AR39: =AT35 -> 0 | AS39: 1690.66 | AT39: =AR39+AS39 -> 1690.66 | AV39: =H39+L39+P39+T39+X39+AB39+AF39+AJ39+AR39 -> 0 | AW39: =I39+M39+Q39+U39+Y39+AC39+AG39+AK39+AS39 -> 877526.37 | AX39: =J39+N39+R39+V39+Z39+AD39+AH39+AL39+AT39 -> 877526.37
B40: 📋 MOD SNAPSHOT — What does this modification do? (enter description: funding increase, scope change, new clause, administrative, etc.)
B42: P00009 | D42: Mixed | E42: • Provide incremental funding of $1,792,646.95 • Update DFARS 252.232-7007 Limitation of Government Obligation | G42: CEILING | H42: =J38 -> 593717.36 | I42: 0 | J42: =H42+I42 -> 593717.36 | L42: =N38 -> 727970.79 | M42: 0 | N42: =L42+M42 -> 727970.79 | P42: =R38 -> 869923.61 | Q42: 0 | R42: =P42+Q42 -> 869923.61 | T42: =V38 -> 688014.82 | U42: 0 | V42: =T42+U42 -> 688014.82 | X42: =Z38 -> 33772.5 | Y42: 0 | Z42: =X42+Y42 -> 33772.5 | AB42: =AD38 -> 199225.6 | AC42: 0 | AD42: =AB42+AC42 -> 199225.6 | AF42: =AH38 -> 268485.99 | AG42: 0 | AH42: =AF42+AG42 -> 268485.99 | AJ42: =AL38 -> 132000 | AK42: 0 | AL42: =AJ42+AK42 -> 132000 | AN42: =AP38 -> 10144 | AO42: 0 | AP42: =AN42+AO42 -> 10144 | AR42: =AT38 -> 10144 | AS42: 0 | AT42: =AR42+AS42 -> 10144 | AV42: =H42+L42+P42+T42+X42+AB42+AF42+AJ42+AR42 -> 3523254.7 | AW42: =I42+M42+Q42+U42+Y42+AC42+AG42+AK42+AS42 -> 0 | AX42: =J42+N42+R42+V42+Z42+AD42+AH42+AL42+AT42 -> 3523254.7
G43: FUNDING | H43: =J39 -> 98952.89 | I43: 333966.02 | J43: =H43+I43 -> 432918.91 | L43: =N39 -> 151660.58 | M43: 409483.57 | N43: =L43+M43 -> 561144.15 | P43: =R39 -> 181234.09 | Q43: 489332.03 | R43: =P43+Q43 -> 670566.12 | T43: =V39 -> 114669.14 | U43: 387008.33 | V43: =T43+U43 -> 501677.47 | X43: =Z39 -> 5628.75 | Y43: 18997.03 | Z43: =X43+Y43 -> 24625.78 | AB43: =AD39 -> 33204.27 | AC43: 112064.4 | AD43: =AB43+AC43 -> 145268.67 | AF43: =AH39 -> 268485.99 | AG43: 0 | AH43: =AF43+AG43 -> 268485.99 | AJ43: =AL39 -> 22000 | AK43: 38486.24 | AL43: =AJ43+AK43 -> 60486.24 | AN43: =AP39 -> 1690.66 | AO43: 3309.33 | AP43: =AN43+AO43 -> 4999.99 | AR43: =AT39 -> 1690.66 | AS43: 3309.33 | AT43: =AR43+AS43 -> 4999.99 | AV43: =H43+L43+P43+T43+X43+AB43+AF43+AJ43+AR43 -> 877526.37 | AW43: =I43+M43+Q43+U43+Y43+AC43+AG43+AK43+AS43 -> 1792647 | AX43: =J43+N43+R43+V43+Z43+AD43+AH43+AL43+AT43 -> 2670173.3
B44: 📋 MOD SNAPSHOT — What does this modification do? (enter description: funding increase, scope change, new clause, administrative, etc.)
B46: P00010 | G46: CEILING | H46: =J42 -> 593717.36 | I46: 0 | J46: =H46+I46 -> 593717.36 | L46: =N42 -> 727970.79 | M46: 0 | N46: =L46+M46 -> 727970.79 | P46: =R42 -> 869923.61 | Q46: 0 | R46: =P46+Q46 -> 869923.61 | T46: =V42 -> 688014.82 | U46: 0 | V46: =T46+U46 -> 688014.82 | X46: =Z42 -> 33772.5 | Y46: 0 | Z46: =X46+Y46 -> 33772.5 | AB46: =AD42 -> 199225.6 | AC46: 0 | AD46: =AB46+AC46 -> 199225.6 | AF46: =AH42 -> 268485.99 | AG46: 0 | AH46: =AF46+AG46 -> 268485.99 | AJ46: =AL42 -> 132000 | AK46: 0 | AL46: =AJ46+AK46 -> 132000 | AN46: =AP42 -> 10144 | AO46: 0 | AP46: =AN46+AO46 -> 10144 | AR46: =AT42 -> 10144 | AS46: 0 | AT46: =AR46+AS46 -> 10144 | AV46: =H46+L46+P46+T46+X46+AB46+AF46+AJ46+AR46 -> 3523254.7 | AW46: =I46+M46+Q46+U46+Y46+AC46+AG46+AK46+AS46 -> 0 | AX46: =J46+N46+R46+V46+Z46+AD46+AH46+AL46+AT46 -> 3523254.7
G47: FUNDING | H47: =J43 -> 432918.91 | I47: 0 | J47: =H47+I47 -> 432918.91 | L47: =N43 -> 561144.15 | M47: 0 | N47: =L47+M47 -> 561144.15 | P47: =R43 -> 670566.12 | Q47: 0 | R47: =P47+Q47 -> 670566.12 | T47: =V43 -> 501677.47 | U47: 0 | V47: =T47+U47 -> 501677.47 | X47: =Z43 -> 24625.78 | Y47: 0 | Z47: =X47+Y47 -> 24625.78 | AB47: =AD43 -> 145268.67 | AC47: 0 | AD47: =AB47+AC47 -> 145268.67 | AF47: =AH43 -> 268485.99 | AG47: 0 | AH47: =AF47+AG47 -> 268485.99 | AJ47: =AL43 -> 60486.24 | AK47: 0 | AL47: =AJ47+AK47 -> 60486.24 | AN47: =AP43 -> 4999.99 | AO47: 0 | AP47: =AN47+AO47 -> 4999.99 | AR47: =AT43 -> 4999.99 | AS47: 0 | AT47: =AR47+AS47 -> 4999.99 | AV47: =H47+L47+P47+T47+X47+AB47+AF47+AJ47+AR47 -> 2670173.3 | AW47: =I47+M47+Q47+U47+Y47+AC47+AG47+AK47+AS47 -> 0 | AX47: =J47+N47+R47+V47+Z47+AD47+AH47+AL47+AT47 -> 2670173.3
B48: 📋 MOD SNAPSHOT — What does this modification do? (enter description: funding increase, scope change, new clause, administrative, etc.)
B50: P00011 | G50: CEILING | H50: =J46 -> 593717.36 | I50: 0 | J50: =H50+I50 -> 593717.36 | L50: =N46 -> 727970.79 | M50: 0 | N50: =L50+M50 -> 727970.79 | P50: =R46 -> 869923.61 | Q50: 0 | R50: =P50+Q50 -> 869923.61 | T50: =V46 -> 688014.82 | U50: 0 | V50: =T50+U50 -> 688014.82 | X50: =Z46 -> 33772.5 | Y50: 0 | Z50: =X50+Y50 -> 33772.5 | AB50: =AD46 -> 199225.6 | AC50: 0 | AD50: =AB50+AC50 -> 199225.6 | AF50: =AH46 -> 268485.99 | AG50: 0 | AH50: =AF50+AG50 -> 268485.99 | AJ50: =AL46 -> 132000 | AK50: 0 | AL50: =AJ50+AK50 -> 132000 | AN50: =AP46 -> 10144 | AO50: 0 | AP50: =AN50+AO50 -> 10144 | AR50: =AT46 -> 10144 | AS50: 0 | AT50: =AR50+AS50 -> 10144 | AV50: =H50+L50+P50+T50+X50+AB50+AF50+AJ50+AR50 -> 3523254.7 | AW50: =I50+M50+Q50+U50+Y50+AC50+AG50+AK50+AS50 -> 0 | AX50: =J50+N50+R50+V50+Z50+AD50+AH50+AL50+AT50 -> 3523254.7
G51: FUNDING | H51: =J47 -> 432918.91 | I51: 0 | J51: =H51+I51 -> 432918.91 | L51: =N47 -> 561144.15 | M51: 0 | N51: =L51+M51 -> 561144.15 | P51: =R47 -> 670566.12 | Q51: 0 | R51: =P51+Q51 -> 670566.12 | T51: =V47 -> 501677.47 | U51: 0 | V51: =T51+U51 -> 501677.47 | X51: =Z47 -> 24625.78 | Y51: 0 | Z51: =X51+Y51 -> 24625.78 | AB51: =AD47 -> 145268.67 | AC51: 0 | AD51: =AB51+AC51 -> 145268.67 | AF51: =AH47 -> 268485.99 | AG51: 0 | AH51: =AF51+AG51 -> 268485.99 | AJ51: =AL47 -> 60486.24 | AK51: 0 | AL51: =AJ51+AK51 -> 60486.24 | AN51: =AP47 -> 4999.99 | AO51: 0 | AP51: =AN51+AO51 -> 4999.99 | AR51: =AT47 -> 4999.99 | AS51: 0 | AT51: =AR51+AS51 -> 4999.99 | AV51: =H51+L51+P51+T51+X51+AB51+AF51+AJ51+AR51 -> 2670173.3 | AW51: =I51+M51+Q51+U51+Y51+AC51+AG51+AK51+AS51 -> 0 | AX51: =J51+N51+R51+V51+Z51+AD51+AH51+AL51+AT51 -> 2670173.3
B52: 📋 MOD SNAPSHOT — What does this modification do? (enter description: funding increase, scope change, new clause, administrative, etc.)
...

Sheet 💼 Labor Forecast
A1: 💼 LABOR FORECAST — CPFF CLINs 1006 | 1007 | 1008
A2: Enter hours in BLUE cells. Cost = Hours × Burdened Rate × 1.08 (CPFF fee). CPFF CLIN Forecast cells in monthly burn tabs auto-populate from this sheet.
A3: CPFF FEE RATE (Cost Plus Fixed Fee — applied to all labor costs): | H3: Fee Rate: | I3: 0.08 | J3: ← Editable. Default = 8%. Changing updates ALL cost calculations automatically.
A4: CLIN | C4: Labor Category | D4: Employee | E4: Company | F4: Burdened Rate ($/hr) | G4: Updated Rates | H4: Feb-Mar (M1) | J4: April | L4: May | N4: June | P4: July | R4: August | T4: September | V4: October | X4: November | Z4: December | AB4: January | AD4: Feb 1-23 | AF4: ANNUAL TOTAL
H5: Hours | I5: Cost+Fee ($) | J5: Hours | K5: Cost+Fee ($) | L5: Hours | M5: Cost+Fee ($) | N5: Hours | O5: Cost+Fee ($) | P5: Hours | Q5: Cost+Fee ($) | R5: Hours | S5: Cost+Fee ($) | T5: Hours | U5: Cost+Fee ($) | V5: Hours | W5: Cost+Fee ($) | X5: Hours | Y5: Cost+Fee ($) | Z5: Hours | AA5: Cost+Fee ($) | AB5: Hours | AC5: Cost+Fee ($) | AD5: Hours | AE5: Cost+Fee ($) | AF5: Total Hrs | AG5: Total Cost+Fee ($)
A6: CLIN 1006 — Software Maintenance
A7: 1006 | C7: Software Engineer - Mid | F7: 146.63 | H7: 104 | I7: =IFERROR(H7*$F$7*(1+$I$3),0) -> 16469.482 | J7: 88 | K7: =IFERROR(J7*$F$7*(1+$I$3),0) -> 13935.715 | L7: 84 | M7: =IFERROR(L7*$F$7*(1+$I$3),0) -> 13302.274 | N7: 84 | O7: =IFERROR(N7*$F$7*(1+$I$3),0) -> 13302.274 | P7: 92 | Q7: =IFERROR(P7*$F$7*(1+$I$3),0) -> 14569.157 | R7: 84 | S7: =IFERROR(R7*$F$7*(1+$I$3),0) -> 13302.274 | T7: 88 | U7: =IFERROR(T7*$F$7*(1+$I$3),0) -> 13935.715 | V7: 88 | W7: =IFERROR(V7*$F$7*(1+$I$3),0) -> 13935.715 | X7: 80 | Y7: =IFERROR(X7*$F$7*(1+$I$3),0) -> 12668.832 | Z7: 88 | AA7: =IFERROR(Z7*$F$7*(1+$I$3),0) -> 13935.715 | AB7: 80 | AC7: =IFERROR(AB7*$F$7*(1+$I$3),0) -> 12668.832 | AD7: 68 | AE7: =IFERROR(AD7*$F$7*(1+$I$3),0) -> 10768.507 | AF7: =H7+J7+L7+N7+P7+R7+T7+V7+X7+Z7+AB7+AD7 -> 1028 | AG7: =I7+K7+M7+O7+Q7+S7+U7+W7+Y7+AA7+AC7+AE7 -> 162794.49
A8: 1006 | C8: Software Engineer - Mid | F8: 128.32 | H8: 0 | I8: =IFERROR(H8*$F$8*(1+$I$3),0) -> 0 | J8: 88 | K8: =IFERROR(J8*$F$8*(1+$I$3),0) -> 12195.533 | L8: 84 | M8: =IFERROR(L8*$F$8*(1+$I$3),0) -> 11641.19 | N8: 84 | O8: =IFERROR(N8*$F$8*(1+$I$3),0) -> 11641.19 | P8: 92 | Q8: =IFERROR(P8*$F$8*(1+$I$3),0) -> 12749.875 | R8: 84 | S8: =IFERROR(R8*$F$8*(1+$I$3),0) -> 11641.19 | T8: 88 | U8: =IFERROR(T8*$F$8*(1+$I$3),0) -> 12195.533 | V8: 88 | W8: =IFERROR(V8*$F$8*(1+$I$3),0) -> 12195.533 | X8: 80 | Y8: =IFERROR(X8*$F$8*(1+$I$3),0) -> 11086.848 | Z8: 88 | AA8: =IFERROR(Z8*$F$8*(1+$I$3),0) -> 12195.533 | AB8: 80 | AC8: =IFERROR(AB8*$F$8*(1+$I$3),0) -> 11086.848 | AD8: 68 | AE8: =IFERROR(AD8*$F$8*(1+$I$3),0) -> 9423.8208 | AF8: =H8+J8+L8+N8+P8+R8+T8+V8+X8+Z8+AB8+AD8 -> 924 | AG8: =I8+K8+M8+O8+Q8+S8+U8+W8+Y8+AA8+AC8+AE8 -> 128053.09
A9: 1006 | C9: Software Engineer - Mid | F9: 131.57 | H9: 104 | I9: =IFERROR(H9*$F$9*(1+$I$3),0) -> 14777.942 | J9: 88 | K9: 11578.68 | L9: 80 | M9: 10525.68 | N9: 88 | O9: 11578.68 | P9: 88 | Q9: 11578.68 | R9: 84 | S9: 11052.18 | T9: 84 | U9: 11052.18 | V9: 88 | W9: 11578.68 | X9: 76 | Y9: 9999.72 | Z9: 80 | AA9: 10525.68 | AB9: 76 | AC9: 9999.72 | AD9: 68 | AE9: 8946.72 | AF9: =H9+J9+L9+N9+P9+R9+T9+V9+X9+Z9+AB9+AD9 -> 1004 | AG9: =I9+K9+M9+O9+Q9+S9+U9+W9+Y9+AA9+AC9+AE9 -> 133194.54
A10: 1006 | C10: Software Engineer - Senior | F10: 159.18 | H10: 104 | I10: =IFERROR(H10*$F$10*(1+$I$3),0) -> 17879.098 | J10: 88 | K10: =IFERROR(J10*$F$10*(1+$I$3),0) -> 15128.467 | L10: 84 | M10: =IFERROR(L10*$F$10*(1+$I$3),0) -> 14440.81 | N10: 84 | O10: =IFERROR(N10*$F$10*(1+$I$3),0) -> 14440.81 | P10: 92 | Q10: =IFERROR(P10*$F$10*(1+$I$3),0) -> 15816.125 | R10: 84 | S10: =IFERROR(R10*$F$10*(1+$I$3),0) -> 14440.81 | T10: 88 | U10: =IFERROR(T10*$F$10*(1+$I$3),0) -> 15128.467 | V10: 88 | W10: =IFERROR(V10*$F$10*(1+$I$3),0) -> 15128.467 | X10: 80 | Y10: =IFERROR(X10*$F$10*(1+$I$3),0) -> 13753.152 | Z10: 88 | AA10: =IFERROR(Z10*$F$10*(1+$I$3),0) -> 15128.467 | AB10: 80 | AC10: =IFERROR(AB10*$F$10*(1+$I$3),0) -> 13753.152 | AD10: 68 | AE10: =IFERROR(AD10*$F$10*(1+$I$3),0) -> 11690.179 | AF10: =H10+J10+L10+N10+P10+R10+T10+V10+X10+Z10+AB10+AD10 -> 1028 | AG10: =I10+K10+M10+O10+Q10+S10+U10+W10+Y10+AA10+AC10+AE10 -> 176728
A11: 1006 | C11: Software Engineer - Senior | F11: 155.61 | G11: 128.21 | H11: 0 | I11: =IFERROR(H11*$F$11*(1+$I$3),0) -> 0 | J11: 0 | K11: =IFERROR(J11*$F$11*(1+$I$3),0) -> 0 | L11: 0 | M11: =IFERROR(L11*$F$11*(1+$I$3),0) -> 0 | N11: 0 | O11: =IFERROR(N11*$F$11*(1+$I$3),0) -> 0 | P11: 0 | Q11: =IFERROR(P11*$F$11*(1+$I$3),0) -> 0 | R11: 0 | S11: =IFERROR(R11*$F$11*(1+$I$3),0) -> 0 | T11: 0 | U11: =IFERROR(T11*$F$11*(1+$I$3),0) -> 0 | V11: 0 | W11: =IFERROR(V11*$F$11*(1+$I$3),0) -> 0 | X11: 0 | Y11: =IFERROR(X11*$F$11*(1+$I$3),0) -> 0 | Z11: 0 | AA11: =IFERROR(Z11*$F$11*(1+$I$3),0) -> 0 | AB11: 0 | AC11: =IFERROR(AB11*$F$11*(1+$I$3),0) -> 0 | AD11: 0 | AE11: =IFERROR(AD11*$F$11*(1+$I$3),0) -> 0 | AF11: =H11+J11+L11+N11+P11+R11+T11+V11+X11+Z11+AB11+AD11 -> 0 | AG11: =I11+K11+M11+O11+Q11+S11+U11+W11+Y11+AA11+AC11+AE11 -> 0
A12: 1006 | C12: Software Engineer - Senior | F12: 166.81 | H12: 104 | I12: =IFERROR(H12*$F$12*(1+$I$3),0) -> 18736.099 | J12: 88 | K12: 14679.9 | L12: 80 | M12: 13345.02 | N12: 88 | O12: 14679.9 | Q12: 14679.9 | S12: 14012.46 | T12: 0 | U12: 14012.46 | V12: 0 | W12: =IFERROR(V12*$F$12*(1+$I$3),0) -> 0 | X12: 0 | Y12: =IFERROR(X12*$F$12*(1+$I$3),0) -> 0 | Z12: 0 | AA12: =IFERROR(Z12*$F$12*(1+$I$3),0) -> 0 | AB12: 0 | AC12: =IFERROR(AB12*$F$12*(1+$I$3),0) -> 0 | AD12: 0 | AE12: =IFERROR(AD12*$F$12*(1+$I$3),0) -> 0 | AF12: =H12+J12+L12+N12+P12+R12+T12+V12+X12+Z12+AB12+AD12 -> 360 | AG12: =I12+K12+M12+O12+Q12+S12+U12+W12+Y12+AA12+AC12+AE12 -> 104145.74
A13: 1006 | C13: Software Engineer - Senior | F13: 89.63 | H13: 104 | I13: =IFERROR(H13*$F$13*(1+$I$3),0) -> 10067.242 | J13: 88 | K13: 7887.78 | L13: 80 | M13: 7170.66 | N13: 88 | O13: 7887.78 | P13: 88 | Q13: 7887.78 | R13: 84 | S13: 7529.22 | T13: 84 | U13: 7529.22 | V13: 88 | W13: 7887.78 | X13: 76 | Y13: 6812.1 | Z13: 80 | AA13: 7170.66 | AB13: 76 | AC13: 6812.1 | AD13: 68 | AE13: 6094.98 | AF13: =H13+J13+L13+N13+P13+R13+T13+V13+X13+Z13+AB13+AD13 -> 1004 | AG13: =I13+K13+M13+O13+Q13+S13+U13+W13+Y13+AA13+AC13+AE13 -> 90737.302
A14: 1006 | C14: Systems Engineer - Mid | F14: 138.49 | H14: 0 | I14: =IFERROR(H14*$F$14*(1+$I$3),0) -> 0 | J14: 0 | K14: =IFERROR(J14*$F$14*(1+$I$3),0) -> 0 | L14: 0 | M14: =IFERROR(L14*$F$14*(1+$I$3),0) -> 0 | N14: 0 | O14: =IFERROR(N14*$F$14*(1+$I$3),0) -> 0 | P14: 0 | Q14: =IFERROR(P14*$F$14*(1+$I$3),0) -> 0 | R14: 0 | S14: =IFERROR(R14*$F$14*(1+$I$3),0) -> 0 | T14: 0 | U14: =IFERROR(T14*$F$14*(1+$I$3),0) -> 0 | V14: 0 | W14: =IFERROR(V14*$F$14*(1+$I$3),0) -> 0 | X14: 0 | Y14: =IFERROR(X14*$F$14*(1+$I$3),0) -> 0 | Z14: 0 | AA14: =IFERROR(Z14*$F$14*(1+$I$3),0) -> 0 | AB14: 0 | AC14: =IFERROR(AB14*$F$14*(1+$I$3),0) -> 0 | AD14: 0 | AE14: =IFERROR(AD14*$F$14*(1+$I$3),0) -> 0 | AF14: =H14+J14+L14+N14+P14+R14+T14+V14+X14+Z14+AB14+AD14 -> 0 | AG14: =I14+K14+M14+O14+Q14+S14+U14+W14+Y14+AA14+AC14+AE14 -> 0
A15: 1006 | C15: Cybersecurity Engineer - Senior | F15: 123.42 | H15: 104 | I15: =IFERROR(H15*$F$15*(1+$I$3),0) -> 13862.534 | J15: 88 | K15: 10861.02 | L15: 80 | M15: 9873.36 | N15: 88 | O15: 10861.02 | P15: 88 | Q15: 10861.02 | R15: 84 | S15: 10367.46 | T15: 84 | U15: 10367.46 | V15: 88 | W15: 10861.02 | X15: 76 | Y15: 9379.8 | Z15: 80 | AA15: 9873.36 | AB15: 76 | AC15: 9379.8 | AD15: 68 | AE15: 8392.68 | AF15: =H15+J15+L15+N15+P15+R15+T15+V15+X15+Z15+AB15+AD15 -> 1004 | AG15: =I15+K15+M15+O15+Q15+S15+U15+W15+Y15+AA15+AC15+AE15 -> 124940.53
A16: 1006 | C16: Test Engineer - Mid | F16: 190 | I16: =IFERROR(H16*$F$16*(1+$I$3),0) -> 0 | K16: =IFERROR(J16*$F$16*(1+$I$3),0) -> 0 | L16: 84 | M16: =IFERROR(L16*$F$16*(1+$I$3),0) -> 17236.8 | N16: 84 | O16: =IFERROR(N16*$F$16*(1+$I$3),0) -> 17236.8 | P16: 92 | Q16: =IFERROR(P16*$F$16*(1+$I$3),0) -> 18878.4 | R16: 84 | S16: =IFERROR(R16*$F$16*(1+$I$3),0) -> 17236.8 | T16: 88 | U16: =IFERROR(T16*$F$16*(1+$I$3),0) -> 18057.6 | V16: 88 | W16: =IFERROR(V16*$F$16*(1+$I$3),0) -> 18057.6 | Y16: =IFERROR(X16*$F$16*(1+$I$3),0) -> 0 | AA16: =IFERROR(Z16*$F$16*(1+$I$3),0) -> 0 | AC16: =IFERROR(AB16*$F$16*(1+$I$3),0) -> 0 | AE16: =IFERROR(AD16*$F$16*(1+$I$3),0) -> 0 | AG16: =I16+K16+M16+O16+Q16+S16+U16+W16+Y16+AA16+AC16+AE16 -> 106704
A17: 1006 | C17: TOTAL — CLIN 1006 | H17: =SUM(H7:H16) -> 624 | I17: =SUM(I7:I16) -> 91792.397 | J17: =SUM(J7:J16) -> 616 | K17: =SUM(K7:K16) -> 86267.095 | L17: =SUM(L7:L16) -> 656 | M17: =SUM(M7:M16) -> 97535.794 | N17: =SUM(N7:N16) -> 688 | O17: =SUM(O7:O16) -> 101628.45 | ... AG17: =SUM(AG7:AG16) -> 1027297.7
A19: CLIN 1007 — Software Development
A20: 1007 | C20: Software Engineer - Mid | F20: 146.63 | H20: 104 | I20: =IFERROR(H20*$F$20*(1+$I$3),0) -> 16469.482 | J20: 88 | K20: =IFERROR(J20*$F$20*(1+$I$3),0) -> 13935.715 | L20: 84 | M20: =IFERROR(L20*$F$20*(1+$I$3),0) -> 13302.274 | N20: 84 | O20: =IFERROR(N20*$F$20*(1+$I$3),0) -> 13302.274 | P20: 92 | Q20: =IFERROR(P20*$F$20*(1+$I$3),0) -> 14569.157 | R20: 84 | S20: =IFERROR(R20*$F$20*(1+$I$3),0) -> 13302.274 | T20: 88 | U20: =IFERROR(T20*$F$20*(1+$I$3),0) -> 13935.715 | V20: 88 | W20: =IFERROR(V20*$F$20*(1+$I$3),0) -> 13935.715 | X20: 80 | Y20: =IFERROR(X20*$F$20*(1+$I$3),0) -> 12668.832 | Z20: 88 | AA20: =IFERROR(Z20*$F$20*(1+$I$3),0) -> 13935.715 | AB20: 80 | AC20: =IFERROR(AB20*$F$20*(1+$I$3),0) -> 12668.832 | AD20: 68 | AE20: =IFERROR(AD20*$F$20*(1+$I$3),0) -> 10768.507 | AF20: =H20+J20+L20+N20+P20+R20+T20+V20+X20+Z20+AB20+AD20 -> 1028 | AG20: =I20+K20+M20+O20+Q20+S20+U20+W20+Y20+AA20+AC20+AE20 -> 162794.49
A21: 1007 | C21: Software Engineer - Mid | F21: 128.32 | H21: 0 | I21: =IFERROR(H21*$F$21*(1+$I$3),0) -> 0 | J21: 88 | K21: =IFERROR(J21*$F$21*(1+$I$3),0) -> 12195.533 | L21: 84 | M21: =IFERROR(L21*$F$21*(1+$I$3),0) -> 11641.19 | N21: 84 | O21: =IFERROR(N21*$F$21*(1+$I$3),0) -> 11641.19 | P21: 92 | Q21: =IFERROR(P21*$F$21*(1+$I$3),0) -> 12749.875 | R21: 84 | S21: =IFERROR(R21*$F$21*(1+$I$3),0) -> 11641.19 | T21: 88 | U21: =IFERROR(T21*$F$21*(1+$I$3),0) -> 12195.533 | V21: 88 | W21: =IFERROR(V21*$F$21*(1+$I$3),0) -> 12195.533 | X21: 80 | Y21: =IFERROR(X21*$F$21*(1+$I$3),0) -> 11086.848 | Z21: 88 | AA21: =IFERROR(Z21*$F$21*(1+$I$3),0) -> 12195.533 | AB21: 80 | AC21: =IFERROR(AB21*$F$21*(1+$I$3),0) -> 11086.848 | AD21: 68 | AE21: =IFERROR(AD21*$F$21*(1+$I$3),0) -> 9423.8208 | AF21: =H21+J21+L21+N21+P21+R21+T21+V21+X21+Z21+AB21+AD21 -> 924 | AG21: =I21+K21+M21+O21+Q21+S21+U21+W21+Y21+AA21+AC21+AE21 -> 128053.09
A22: 1007 | C22: Software Engineer - Mid | F22: 131.57 | H22: 104 | I22: =IFERROR(H22*$F$22*(1+$I$3),0) -> 14777.942 | J22: 88 | K22: 11578.68 | L22: 80 | M22: 10525.68 | N22: 88 | O22: 11578.68 | P22: 88 | Q22: 11578.68 | R22: 84 | S22: 11052.18 | T22: 84 | U22: 11052.18 | V22: 88 | W22: 11578.68 | X22: 76 | Y22: 9999.72 | Z22: 80 | AA22: 10525.68 | AB22: 76 | AC22: 9999.72 | AD22: 68 | AE22: 8946.72 | AF22: =H22+J22+L22+N22+P22+R22+T22+V22+X22+Z22+AB22+AD22 -> 1004 | AG22: =I22+K22+M22+O22+Q22+S22+U22+W22+Y22+AA22+AC22+AE22 -> 133194.54
A23: 1007 | C23: Software Engineer - Mid | F23: 89.63 | H23: 104 | I23: =IFERROR(H23*$F$23*(1+$I$3),0) -> 10067.242 | J23: 88 | K23: 7887.78 | L23: 80 | M23: 7170.66 | N23: 88 | O23: 7887.78 | P23: 88 | Q23: 7887.78 | R23: 84 | S23: 7529.22 | T23: 84 | U23: 7529.22 | V23: 88 | W23: 7887.78 | X23: 76 | Y23: 6812.1 | Z23: 80 | AA23: 7170.66 | AB23: 76 | AC23: 6812.1 | AD23: 68 | AE23: 6094.98 | AF23: =H23+J23+L23+N23+P23+R23+T23+V23+X23+Z23+AB23+AD23 -> 1004 | AG23: =I23+K23+M23+O23+Q23+S23+U23+W23+Y23+AA23+AC23+AE23 -> 90737.302
A24: 1007 | C24: Software Engineer - Senior | F24: 159.18 | H24: 104 | I24: =IFERROR(H24*$F$24*(1+$I$3),0) -> 17879.098 | J24: 88 | K24: =IFERROR(J24*$F$24*(1+$I$3),0) -> 15128.467 | L24: 84 | M24: =IFERROR(L24*$F$24*(1+$I$3),0) -> 14440.81 | N24: 84 | O24: =IFERROR(N24*$F$24*(1+$I$3),0) -> 14440.81 | P24: 92 | Q24: =IFERROR(P24*$F$24*(1+$I$3),0) -> 15816.125 | R24: 84 | S24: =IFERROR(R24*$F$24*(1+$I$3),0) -> 14440.81 | T24: 88 | U24: =IFERROR(T24*$F$24*(1+$I$3),0) -> 15128.467 | V24: 88 | W24: =IFERROR(V24*$F$24*(1+$I$3),0) -> 15128.467 | X24: 80 | Y24: =IFERROR(X24*$F$24*(1+$I$3),0) -> 13753.152 | Z24: 88 | AA24: =IFERROR(Z24*$F$24*(1+$I$3),0) -> 15128.467 | AB24: 80 | AC24: =IFERROR(AB24*$F$24*(1+$I$3),0) -> 13753.152 | AD24: 68 | AE24: =IFERROR(AD24*$F$24*(1+$I$3),0) -> 11690.179 | AF24: =H24+J24+L24+N24+P24+R24+T24+V24+X24+Z24+AB24+AD24 -> 1028 | AG24: =I24+K24+M24+O24+Q24+S24+U24+W24+Y24+AA24+AC24+AE24 -> 176728
A25: 1007 | C25: Software Engineer - Senior | F25: 155.61 | G25: 128.21 | H25: 0 | I25: =IFERROR(H25*$F$25*(1+$I$3),0) -> 0 | J25: 0 | K25: =IFERROR(J25*$F$25*(1+$I$3),0) -> 0 | L25: 0 | M25: =IFERROR(L25*$F$25*(1+$I$3),0) -> 0 | N25: 0 | O25: =IFERROR(N25*$F$25*(1+$I$3),0) -> 0 | P25: 0 | Q25: =IFERROR(P25*$F$25*(1+$I$3),0) -> 0 | R25: 0 | S25: =IFERROR(R25*$F$25*(1+$I$3),0) -> 0 | T25: 0 | U25: =IFERROR(T25*$F$25*(1+$I$3),0) -> 0 | V25: 0 | W25: =IFERROR(V25*$F$25*(1+$I$3),0) -> 0 | X25: 0 | Y25: =IFERROR(X25*$F$25*(1+$I$3),0) -> 0 | Z25: 0 | AA25: =IFERROR(Z25*$F$25*(1+$I$3),0) -> 0 | AB25: 0 | AC25: =IFERROR(AB25*$F$25*(1+$I$3),0) -> 0 | AD25: 0 | AE25: =IFERROR(AD25*$F$25*(1+$I$3),0) -> 0 | AF25: =H25+J25+L25+N25+P25+R25+T25+V25+X25+Z25+AB25+AD25 -> 0 | AG25: =I25+K25+M25+O25+Q25+S25+U25+W25+Y25+AA25+AC25+AE25 -> 0
A26: 1007 | C26: Software Engineer - Senior | F26: 166.81 | H26: 104 | I26: =IFERROR(H26*$F$26*(1+$I$3),0) -> 18736.099 | J26: 88 | K26: 14679.9 | L26: 80 | M26: 13345.02 | N26: 88 | O26: 14679.9 | Q26: 14679.9 | S26: 14012.46 | T26: 0 | U26: 14012.46 | V26: 0 | W26: =IFERROR(V26*$F$26*(1+$I$3),0) -> 0 | X26: 0 | Y26: =IFERROR(X26*$F$26*(1+$I$3),0) -> 0 | Z26: 0 | AA26: =IFERROR(Z26*$F$26*(1+$I$3),0) -> 0 | AB26: 0 | AC26: =IFERROR(AB26*$F$26*(1+$I$3),0) -> 0 | AD26: 0 | AE26: =IFERROR(AD26*$F$26*(1+$I$3),0) -> 0 | AF26: =H26+J26+L26+N26+P26+R26+T26+V26+X26+Z26+AB26+AD26 -> 360 | AG26: =I26+K26+M26+O26+Q26+S26+U26+W26+Y26+AA26+AC26+AE26 -> 104145.74
A27: 1007 | C27: Systems Engineer - Mid | F27: 138.49 | H27: 0 | I27: =IFERROR(H27*$F$27*(1+$I$3),0) -> 0 | J27: 0 | K27: =IFERROR(J27*$F$27*(1+$I$3),0) -> 0 | L27: 0 | M27: =IFERROR(L27*$F$27*(1+$I$3),0) -> 0 | N27: 0 | O27: =IFERROR(N27*$F$27*(1+$I$3),0) -> 0 | P27: 0 | Q27: =IFERROR(P27*$F$27*(1+$I$3),0) -> 0 | R27: 0 | S27: =IFERROR(R27*$F$27*(1+$I$3),0) -> 0 | T27: 0 | U27: =IFERROR(T27*$F$27*(1+$I$3),0) -> 0 | V27: 0 | W27: =IFERROR(V27*$F$27*(1+$I$3),0) -> 0 | X27: 0 | Y27: =IFERROR(X27*$F$27*(1+$I$3),0) -> 0 | Z27: 0 | AA27: =IFERROR(Z27*$F$27*(1+$I$3),0) -> 0 | AB27: 0 | AC27: =IFERROR(AB27*$F$27*(1+$I$3),0) -> 0 | AD27: 0 | AE27: =IFERROR(AD27*$F$27*(1+$I$3),0) -> 0 | AF27: =H27+J27+L27+N27+P27+R27+T27+V27+X27+Z27+AB27+AD27 -> 0 | AG27: =I27+K27+M27+O27+Q27+S27+U27+W27+Y27+AA27+AC27+AE27 -> 0
A28: 1007 | C28: Cybersecurity Engineer - Senior | F28: 123.42 | H28: 104 | I28: =IFERROR(H28*$F$28*(1+$I$3),0) -> 13862.534 | J28: 88 | K28: 10861.02 | L28: 80 | M28: 9873.36 | N28: 88 | O28: 10861.02 | P28: 88 | Q28: 10861.02 | R28: 84 | S28: 10367.46 | T28: 84 | U28: 10367.46 | V28: 88 | W28: 10861.02 | X28: 76 | Y28: 9379.8 | Z28: 80 | AA28: 9873.36 | AB28: 76 | AC28: 9379.8 | AD28: 68 | AE28: 8392.68 | AF28: =H28+J28+L28+N28+P28+R28+T28+V28+X28+Z28+AB28+AD28 -> 1004 | AG28: =I28+K28+M28+O28+Q28+S28+U28+W28+Y28+AA28+AC28+AE28 -> 124940.53
A29: 1007 | C29: Test Engineer - Mid | F29: 190 | I29: =IFERROR(H29*$F$29*(1+$I$3),0) -> 0 | K29: =IFERROR(J29*$F$29*(1+$I$3),0) -> 0 | L29: 84 | M29: =IFERROR(L29*$F$29*(1+$I$3),0) -> 17236.8 | N29: 84 | O29: =IFERROR(N29*$F$29*(1+$I$3),0) -> 17236.8 | P29: 92 | Q29: =IFERROR(P29*$F$29*(1+$I$3),0) -> 18878.4 | R29: 84 | S29: =IFERROR(R29*$F$29*(1+$I$3),0) -> 17236.8 | T29: 88 | U29: =IFERROR(T29*$F$29*(1+$I$3),0) -> 18057.6 | V29: 88 | W29: =IFERROR(V29*$F$29*(1+$I$3),0) -> 18057.6 | Y29: =IFERROR(X29*$F$29*(1+$I$3),0) -> 0 | AA29: =IFERROR(Z29*$F$29*(1+$I$3),0) -> 0 | AC29: =IFERROR(AB29*$F$29*(1+$I$3),0) -> 0 | AE29: =IFERROR(AD29*$F$29*(1+$I$3),0) -> 0 | AF29: =H29+J29+L29+N29+P29+R29+T29+V29+X29+Z29+AB29+AD29 -> 520 | AG29: =I29+K29+M29+O29+Q29+S29+U29+W29+Y29+AA29+AC29+AE29 -> 106704
A30: 1007 | C30: TOTAL — CLIN 1007 | H30: =SUM(H20:H29) -> 624 | I30: =SUM(I20:I29) -> 91792.397 | J30: =SUM(J20:J29) -> 616 | K30: =SUM(K20:K29) -> 86267.095 | L30: =SUM(L20:L29) -> 656 | M30: =SUM(M20:M29) -> 97535.794 | N30: =SUM(N20:N29) -> 688 | O30: =SUM(O20:O29) -> 101628.45 | ... AG30: =SUM(AG20:AG29) -> 1027297.7
A32: CLIN 1008 — O&M
A33: 1008 | C33: Database Specialist - Senior | F33: 155.61 | G33: 128.21 | H33: 208 | I33: =IFERROR(H33*$F$33*(1+$I$3),0) -> 34956.23 | J33: 176 | K33: =IFERROR(J33*$F$33*(1+$I$3),0) -> 29578.349 | L33: 168 | M33: =IFERROR(L33*$G$33*(1+$I$3),0) -> 23262.422 | N33: 168 | O33: =IFERROR(N33*$G$33*(1+$I$3),0) -> 23262.422 | P33: 184 | Q33: =IFERROR(P33*$G$33*(1+$I$3),0) -> 25477.891 | R33: 168 | S33: =IFERROR(R33*$G$33*(1+$I$3),0) -> 23262.422 | T33: 176 | U33: =IFERROR(T33*$G$33*(1+$I$3),0) -> 24370.157 | V33: 176 | W33: =IFERROR(V33*$G$33*(1+$I$3),0) -> 24370.157 | X33: 160 | Y33: =IFERROR(X33*$G$33*(1+$I$3),0) -> 22154.688 | Z33: 176 | AA33: =IFERROR(Z33*$G$33*(1+$I$3),0) -> 24370.157 | AB33: 160 | AC33: =IFERROR(AB33*$G$33*(1+$I$3),0) -> 22154.688 | AD33: 136 | AE33: =IFERROR(AD33*$G$33*(1+$I$3),0) -> 18831.485 | AF33: =H33+J33+L33+N33+P33+R33+T33+V33+X33+Z33+AB33+AD33 -> 2056 | AG33: =I33+K33+M33+O33+Q33+S33+U33+W33+Y33+AA33+AC33+AE33 -> 296051.07
A34: 1008 | C34: Systems Engineer - Senior | F34: 152.3487 | H34: 0 | I34: =IFERROR(H34*$F$34*(1+$I$3),0) -> 0 | J34: 0 | K34: =IFERROR(J34*$F$34*(1+$I$3),0) -> 0 | L34: 0 | M34: =IFERROR(L34*$F$34*(1+$I$3),0) -> 0 | N34: 0 | O34: =IFERROR(N34*$F$34*(1+$I$3),0) -> 0 | P34: 0 | Q34: =IFERROR(P34*$F$34*(1+$I$3),0) -> 0 | R34: 0 | S34: =IFERROR(R34*$F$34*(1+$I$3),0) -> 0 | T34: 0 | U34: =IFERROR(T34*$F$34*(1+$I$3),0) -> 0 | V34: 0 | W34: =IFERROR(V34*$F$34*(1+$I$3),0) -> 0 | X34: 0 | Y34: =IFERROR(X34*$F$34*(1+$I$3),0) -> 0 | Z34: 0 | AA34: =IFERROR(Z34*$F$34*(1+$I$3),0) -> 0 | AB34: 0 | AC34: =IFERROR(AB34*$F$34*(1+$I$3),0) -> 0 | AD34: 0 | AE34: =IFERROR(AD34*$F$34*(1+$I$3),0) -> 0 | AF34: =H34+J34+L34+N34+P34+R34+T34+V34+X34+Z34+AB34+AD34 -> 0 | AG34: =I34+K34+M34+O34+Q34+S34+U34+W34+Y34+AA34+AC34+AE34 -> 0
A35: 1008 | C35: Systems/nit Engineer | F35: 138.49 | H35: 104 | I35: =IFERROR(H35*$F$35*(1+$I$3),0) -> 15555.197 | J35: 176 | K35: =IFERROR(J35*$F$35*(1+$I$3),0) -> 26324.179 | L35: 84 | M35: =IFERROR(L35*$F$35*(1+$I$3),0) -> 12563.813 | O35: =IFERROR(N35*$F$35*(1+$I$3),0) -> 0 | R35: \ | S35: =IFERROR(R35*$F$35*(1+$I$3),0) -> 0 | U35: =IFERROR(T35*$F$35*(1+$I$3),0) -> 0 | V35: 0 | W35: =IFERROR(V35*$F$35*(1+$I$3),0) -> 0 | X35: 0 | Y35: =IFERROR(X35*$F$35*(1+$I$3),0) -> 0 | Z35: 0 | AA35: =IFERROR(Z35*$F$35*(1+$I$3),0) -> 0 | AB35: 0 | AC35: =IFERROR(AB35*$F$35*(1+$I$3),0) -> 0 | AD35: 0 | AE35: =IFERROR(AD35*$F$35*(1+$I$3),0) -> 0 | AF35: =H35+J35+L35+N35+P35+R35+T35+V35+X35+Z35+AB35+AD35 -> #VALUE! | AG35: =I35+K35+M35+O35+Q35+S35+U35+W35+Y35+AA35+AC35+AE35 -> 54443.189
A36: 1008 | C36: Cybersecurity Engineer - Senior | F36: 123.42 | H36: 0 | I36: =IFERROR(H36*$F$36*(1+$I$3),0) -> 0 | J36: 0 | K36: =IFERROR(J36*$F$36*(1+$I$3),0) -> 0 | L36: 0 | M36: =IFERROR(L36*$F$36*(1+$I$3),0) -> 0 | N36: 0 | O36: =IFERROR(N36*$F$36*(1+$I$3),0) -> 0 | P36: 0 | Q36: =IFERROR(P36*$F$36*(1+$I$3),0) -> 0 | R36: 0 | S36: =IFERROR(R36*$F$36*(1+$I$3),0) -> 0 | T36: 0 | U36: =IFERROR(T36*$F$36*(1+$I$3),0) -> 0 | V36: 0 | W36: =IFERROR(V36*$F$36*(1+$I$3),0) -> 0 | X36: 0 | Y36: =IFERROR(X36*$F$36*(1+$I$3),0) -> 0 | Z36: 0 | AA36: =IFERROR(Z36*$F$36*(1+$I$3),0) -> 0 | AB36: 0 | AC36: =IFERROR(AB36*$F$36*(1+$I$3),0) -> 0 | AD36: 0 | AE36: =IFERROR(AD36*$F$36*(1+$I$3),0) -> 0 | AF36: =H36+J36+L36+N36+P36+R36+T36+V36+X36+Z36+AB36+AD36 -> 0 | AG36: =I36+K36+M36+O36+Q36+S36+U36+W36+Y36+AA36+AC36+AE36 -> 0
A37: 1008
A38: 1008 | C38: TOTAL — CLIN 1008 | I38: =SUM(I33:I36) -> 50511.427 | J38: =SUM(J33:J36) -> 352 | K38: =SUM(K33:K36) -> 55902.528 | L38: =SUM(L33:L36) -> 252 | M38: =SUM(M33:M36) -> 35826.235 | N38: =SUM(N33:N36) -> 168 | O38: =SUM(O33:O36) -> 23262.422 | P38: =SUM(P33:P36) -> 184 | ... AG38: =SUM(AG33:AG36) -> 350494.26

Sheet 📅 Mar
B2: Feb 24–Mar 31 — Monthly Burn Entry (Invoice Month 1)
B3: Blue = enter data | Gray = formula | Green = cross-sheet link. Sub Actuals col locked for non-sub CLINs.
B4: 🟢 CPFF CLINs 1006/1007/1008 — Forecast auto-calculated from 💼 Labor Forecast tab. | FFP/ODC CLINs 1005/1009/1010/1016/1017/1018 — enter Forecast directly in blue cells.
B6: CLIN | C6: Description | D6: Type | E6: Prime Actuals ($) | F6: Sub Actuals ($) | G6: Total Actuals ($) | H6: Forecast ($) | I6: Variance ($) | J6: Notes
B7: ='⚙️ Setup'!B15 -> 1005 | C7: ='⚙️ Setup'!C15 -> Project Management | D7: ='⚙️ Setup'!D15 -> FFP | E7: 45545.44 | F7: 0 | G7: =IFERROR(E7,0)+IFERROR(F7,0) -> 45545.44 | H7: 45545.44 | I7: =G7-H7 -> 0
B8: ='⚙️ Setup'!B16 -> 1006 | C8: ='⚙️ Setup'!C16 -> Software Maintenance | D8: ='⚙️ Setup'!D16 -> CPFF | E8: 139671.71 | G8: =IFERROR(E8,0)+IFERROR(F8,0) -> 139671.71 | H8: ='💼 Labor Forecast'!I17 -> 91792.397 | I8: =G8-H8 -> 47879.313 | J8: • Teammates not provided updated, equal split billing guidance. Therefore, BL teammates all billed 1006, and TH had a split between 1006 + 1007 • Waiss Q. was not forecasted to come back on paternity leave
B9: ='⚙️ Setup'!B17 -> 1007 | C9: ='⚙️ Setup'!C17 -> Software Development | D9: ='⚙️ Setup'!D17 -> CPFF | E9: 90434.31 | G9: =IFERROR(E9,0)+IFERROR(F9,0) -> 90434.31 | H9: ='💼 Labor Forecast'!I30 -> 91792.397 | I9: =G9-H9 -> -1358.0868
B10: ='⚙️ Setup'!B18 -> 1008 | C10: ='⚙️ Setup'!C18 -> O&M | D10: ='⚙️ Setup'!D18 -> CPFF | E10: 18521.33 | F10: 0 | G10: =IFERROR(E10,0)+IFERROR(F10,0) -> 18521.33 | H10: ='💼 Labor Forecast'!I38 -> 50511.427 | I10: =G10-H10 -> -31990.097
B11: ='⚙️ Setup'!B19 -> 1009 | C11: ='⚙️ Setup'!C19 -> Tier 3 Helpdesk | D11: ='⚙️ Setup'!D19 -> FFP | E11: 2590.77 | F11: 0 | G11: =IFERROR(E11,0)+IFERROR(F11,0) -> 2590.77 | H11: 2590.77 | I11: =G11-H11 -> 0
B12: ='⚙️ Setup'!B20 -> 1010 | C12: ='⚙️ Setup'!C20 -> Training | D12: ='⚙️ Setup'!D20 -> FFP | E12: 15283.06 | F12: 0 | G12: =IFERROR(E12,0)+IFERROR(F12,0) -> 15283.06 | H12: 15283.06 | I12: =G12-H12 -> 0
B13: ='⚙️ Setup'!B21 -> 1016 | C13: ='⚙️ Setup'!C21 -> NTIA | D13: ='⚙️ Setup'!D21 -> FFP | E13: 20596.19 | F13: 0 | G13: =IFERROR(E13,0)+IFERROR(F13,0) -> 20596.19 | H13: 20596.19 | I13: =G13-H13 -> 0
B14: ='⚙️ Setup'!B22 -> 1017 | C14: ='⚙️ Setup'!C22 -> Other Direct Costs | D14: ='⚙️ Setup'!D22 -> COST | E14: 13845.75 | F14: 0 | G14: =IFERROR(E14,0)+IFERROR(F14,0) -> 13845.75 | H14: 7000 | I14: =G14-H14 -> 6845.75
B15: ='⚙️ Setup'!B23 -> 1018 | C15: ='⚙️ Setup'!C23 -> Travel | D15: ='⚙️ Setup'!D23 -> COST | F15: 0 | G15: =IFERROR(E15,0)+IFERROR(F15,0) -> 0 | H15: 0 | I15: =G15-H15 -> 0
B16: TOTAL | E16: =SUM(E7:E15) -> 346488.56 | F16: =SUM(F7:F15) -> 0 | G16: =SUM(G7:G15) -> 346488.56 | H16: =SUM(H7:H15) -> 325111.68 | I16: =SUM(I7:I15) -> 21376.879
B18: Detailed Summary of Total Variance
B19: • 1006, 1007 - Q. not in Labor forecast for M1 due to earlier than planned return date from paternity leave; if we were to add his hours into the forecast, we would have had a 3k TOTAL variance (after accounting for the increased Crayon costs) instead of 21K • ODC - Crayon was only projected to be 7k but due to the part of Feb and March being combined the total was a little less than double the projected amount

Sheet 📅 Apr
B2: April — Monthly Burn Entry (M2)
B3: Blue = enter data | Gray = formula | Green = cross-sheet link. Sub Actuals col locked for non-sub CLINs.
B4: 🟢 CPFF CLINs 1006/1007/1008 — Forecast auto-calculated from 💼 Labor Forecast tab. | FFP/ODC CLINs 1005/1009/1010/1016/1017/1018 — enter Forecast directly in blue cells.
B6: CLIN | C6: Description | D6: Type | E6: Prime Actuals ($) | F6: Sub Actuals ($) | G6: Total Actuals ($) | H6: Forecast ($) | I6: Variance ($) | J6: Notes
B7: ='⚙️ Setup'!B15 -> 1005 | C7: ='⚙️ Setup'!C15 -> Project Management | D7: ='⚙️ Setup'!D15 -> FFP | F7: 0 | G7: =IFERROR(E7,0)+IFERROR(F7,0) -> 0 | H7: 50425.31 | I7: =G7-H7 -> -50425.31
B8: ='⚙️ Setup'!B16 -> 1006 | C8: ='⚙️ Setup'!C16 -> Software Maintenance | D8: ='⚙️ Setup'!D16 -> CPFF | F8: 0 | G8: =IFERROR(E8,0)+IFERROR(F8,0) -> 0 | H8: ='💼 Labor Forecast'!K17 -> 86267.095 | I8: =G8-H8 -> -86267.095
B9: ='⚙️ Setup'!B17 -> 1007 | C9: ='⚙️ Setup'!C17 -> Software Development | D9: ='⚙️ Setup'!D17 -> CPFF | F9: 0 | G9: =IFERROR(E9,0)+IFERROR(F9,0) -> 0 | H9: ='💼 Labor Forecast'!K30 -> 86267.095 | I9: =G9-H9 -> -86267.095
B10: ='⚙️ Setup'!B18 -> 1008 | C10: ='⚙️ Setup'!C18 -> O&M | D10: ='⚙️ Setup'!D18 -> CPFF | F10: 0 | G10: =IFERROR(E10,0)+IFERROR(F10,0) -> 0 | H10: ='💼 Labor Forecast'!K38 -> 55902.528 | I10: =G10-H10 -> -55902.528
B11: ='⚙️ Setup'!B19 -> 1009 | C11: ='⚙️ Setup'!C19 -> Tier 3 Helpdesk | D11: ='⚙️ Setup'!D19 -> FFP | F11: 0 | G11: =IFERROR(E11,0)+IFERROR(F11,0) -> 0 | H11: 2868.35 | I11: =G11-H11 -> -2868.35
B12: ='⚙️ Setup'!B20 -> 1010 | C12: ='⚙️ Setup'!C20 -> Training | D12: ='⚙️ Setup'!D20 -> FFP | F12: 0 | G12: =IFERROR(E12,0)+IFERROR(F12,0) -> 0 | H12: 16920.53 | I12: =G12-H12 -> -16920.53
B13: ='⚙️ Setup'!B21 -> 1016 | C13: ='⚙️ Setup'!C21 -> NTIA | D13: ='⚙️ Setup'!D21 -> FFP | F13: 0 | G13: =IFERROR(E13,0)+IFERROR(F13,0) -> 0 | H13: 22802.92 | I13: =G13-H13 -> -22802.92
B14: ='⚙️ Setup'!B22 -> 1017 | C14: ='⚙️ Setup'!C22 -> Other Direct Costs | D14: ='⚙️ Setup'!D22 -> COST | F14: 0 | G14: =IFERROR(E14,0)+IFERROR(F14,0) -> 0 | H14: 97000 | I14: =G14-H14 -> -97000 | J14: SQL (90k), Crayon (7k),
B15: ='⚙️ Setup'!B23 -> 1018 | C15: ='⚙️ Setup'!C23 -> Travel | D15: ='⚙️ Setup'!D23 -> COST | F15: 0 | G15: =IFERROR(E15,0)+IFERROR(F15,0) -> 0 | H15: 0 | I15: =G15-H15 -> 0
B16: TOTAL | E16: =SUM(E7:E15) -> 0 | F16: =SUM(F7:F15) -> 0 | G16: =SUM(G7:G15) -> 0 | H16: =SUM(H7:H15) -> 418453.83 | I16: =SUM(I7:I15) -> -418453.83

Sheet 📅 May
B2: May — Monthly Burn Entry (M3)
B3: Blue = enter data | Gray = formula | Green = cross-sheet link. Sub Actuals col locked for non-sub CLINs.
B4: 🟢 CPFF CLINs 1006/1007/1008 — Forecast auto-calculated from 💼 Labor Forecast tab. | FFP/ODC CLINs 1005/1009/1010/1016/1017/1018 — enter Forecast directly in blue cells.
B6: CLIN | C6: Description | D6: Type | E6: Prime Actuals ($) | F6: Sub Actuals ($) | G6: Total Actuals ($) | H6: Forecast ($) | I6: Variance ($) | J6: Notes
B7: ='⚙️ Setup'!B15 -> 1005 | C7: ='⚙️ Setup'!C15 -> Project Management | D7: ='⚙️ Setup'!D15 -> FFP | F7: 0 | G7: =IFERROR(E7,0)+IFERROR(F7,0) -> 0 | H7: 48798.69 | I7: =G7-H7 -> -48798.69
B8: ='⚙️ Setup'!B16 -> 1006 | C8: ='⚙️ Setup'!C16 -> Software Maintenance | D8: ='⚙️ Setup'!D16 -> CPFF | F8: 0 | G8: =IFERROR(E8,0)+IFERROR(F8,0) -> 0 | H8: ='💼 Labor Forecast'!M17 -> 97535.794 | I8: =G8-H8 -> -97535.794
B9: ='⚙️ Setup'!B17 -> 1007 | C9: ='⚙️ Setup'!C17 -> Software Development | D9: ='⚙️ Setup'!D17 -> CPFF | F9: 0 | G9: =IFERROR(E9,0)+IFERROR(F9,0) -> 0 | H9: ='💼 Labor Forecast'!M30 -> 97535.794 | I9: =G9-H9 -> -97535.794
B10: ='⚙️ Setup'!B18 -> 1008 | C10: ='⚙️ Setup'!C18 -> O&M | D10: ='⚙️ Setup'!D18 -> CPFF | F10: 0 | G10: =IFERROR(E10,0)+IFERROR(F10,0) -> 0 | H10: ='💼 Labor Forecast'!M38 -> 35826.235 | I10: =G10-H10 -> -35826.235
B11: ='⚙️ Setup'!B19 -> 1009 | C11: ='⚙️ Setup'!C19 -> Tier 3 Helpdesk | D11: ='⚙️ Setup'!D19 -> FFP | F11: 0 | G11: =IFERROR(E11,0)+IFERROR(F11,0) -> 0 | H11: 2775.82 | I11: =G11-H11 -> -2775.82
B12: ='⚙️ Setup'!B20 -> 1010 | C12: ='⚙️ Setup'!C20 -> Training | D12: ='⚙️ Setup'!D20 -> FFP | F12: 0 | G12: =IFERROR(E12,0)+IFERROR(F12,0) -> 0 | H12: 16374.71 | I12: =G12-H12 -> -16374.71
B13: ='⚙️ Setup'!B21 -> 1016 | C13: ='⚙️ Setup'!C21 -> NTIA | D13: ='⚙️ Setup'!D21 -> FFP | F13: 0 | G13: =IFERROR(E13,0)+IFERROR(F13,0) -> 0 | H13: 22067.34 | I13: =G13-H13 -> -22067.34
B14: ='⚙️ Setup'!B22 -> 1017 | C14: ='⚙️ Setup'!C22 -> Other Direct Costs | D14: ='⚙️ Setup'!D22 -> COST | F14: 0 | G14: =IFERROR(E14,0)+IFERROR(F14,0) -> 0 | H14: 7000 | I14: =G14-H14 -> -7000
B15: ='⚙️ Setup'!B23 -> 1018 | C15: ='⚙️ Setup'!C23 -> Travel | D15: ='⚙️ Setup'!D23 -> COST | F15: 0 | G15: =IFERROR(E15,0)+IFERROR(F15,0) -> 0 | H15: 0 | I15: =G15-H15 -> 0
B16: TOTAL | E16: =SUM(E7:E15) -> 0 | F16: =SUM(F7:F15) -> 0 | G16: =SUM(G7:G15) -> 0 | H16: =SUM(H7:H15) -> 327914.38 | I16: =SUM(I7:I15) -> -327914.38

Sheet 📅 Jun
B2: June — Monthly Burn Entry (M4)
B3: Blue = enter data | Gray = formula | Green = cross-sheet link. Sub Actuals col locked for non-sub CLINs.
B4: 🟢 CPFF CLINs 1006/1007/1008 — Forecast auto-calculated from 💼 Labor Forecast tab. | FFP/ODC CLINs 1005/1009/1010/1016/1017/1018 — enter Forecast directly in blue cells.
B6: CLIN | C6: Description | D6: Type | E6: Prime Actuals ($) | F6: Sub Actuals ($) | G6: Total Actuals ($) | H6: Forecast ($) | I6: Variance ($) | J6: Notes
B7: ='⚙️ Setup'!B15 -> 1005 | C7: ='⚙️ Setup'!C15 -> Project Management | D7: ='⚙️ Setup'!D15 -> FFP | F7: 0 | G7: =IFERROR(E7,0)+IFERROR(F7,0) -> 0 | H7: 50425.31 | I7: =G7-H7 -> -50425.31
B8: ='⚙️ Setup'!B16 -> 1006 | C8: ='⚙️ Setup'!C16 -> Software Maintenance | D8: ='⚙️ Setup'!D16 -> CPFF | G8: =IFERROR(E8,0)+IFERROR(F8,0) -> 0 | H8: ='💼 Labor Forecast'!O17 -> 101628.45 | I8: =G8-H8 -> -101628.45
B9: ='⚙️ Setup'!B17 -> 1007 | C9: ='⚙️ Setup'!C17 -> Software Development | D9: ='⚙️ Setup'!D17 -> CPFF | F9: 0 | G9: =IFERROR(E9,0)+IFERROR(F9,0) -> 0 | H9: ='💼 Labor Forecast'!O30 -> 101628.45 | I9: =G9-H9 -> -101628.45
B10: ='⚙️ Setup'!B18 -> 1008 | C10: ='⚙️ Setup'!C18 -> O&M | D10: ='⚙️ Setup'!D18 -> CPFF | F10: 0 | G10: =IFERROR(E10,0)+IFERROR(F10,0) -> 0 | H10: ='💼 Labor Forecast'!O38 -> 23262.422 | I10: =G10-H10 -> -23262.422
B11: ='⚙️ Setup'!B19 -> 1009 | C11: ='⚙️ Setup'!C19 -> Tier 3 Helpdesk | D11: ='⚙️ Setup'!D19 -> FFP | F11: 0 | G11: =IFERROR(E11,0)+IFERROR(F11,0) -> 0 | H11: 2868.35 | I11: =G11-H11 -> -2868.35
B12: ='⚙️ Setup'!B20 -> 1010 | C12: ='⚙️ Setup'!C20 -> Training | D12: ='⚙️ Setup'!D20 -> FFP | F12: 0 | G12: =IFERROR(E12,0)+IFERROR(F12,0) -> 0 | H12: 16920.53 | I12: =G12-H12 -> -16920.53
B13: ='⚙️ Setup'!B21 -> 1016 | C13: ='⚙️ Setup'!C21 -> NTIA | D13: ='⚙️ Setup'!D21 -> FFP | F13: 0 | G13: =IFERROR(E13,0)+IFERROR(F13,0) -> 0 | H13: 22802.92 | I13: =G13-H13 -> -22802.92
B14: ='⚙️ Setup'!B22 -> 1017 | C14: ='⚙️ Setup'!C22 -> Other Direct Costs | D14: ='⚙️ Setup'!D22 -> COST | F14: 0 | G14: =IFERROR(E14,0)+IFERROR(F14,0) -> 0 | H14: 7000 | I14: =G14-H14 -> -7000
B15: ='⚙️ Setup'!B23 -> 1018 | C15: ='⚙️ Setup'!C23 -> Travel | D15: ='⚙️ Setup'!D23 -> COST | F15: 0 | G15: =IFERROR(E15,0)+IFERROR(F15,0) -> 0 | H15: 0 | I15: =G15-H15 -> 0
B16: TOTAL | E16: =SUM(E7:E15) -> 0 | F16: =SUM(F7:F15) -> 0 | G16: =SUM(G7:G15) -> 0 | H16: =SUM(H7:H15) -> 326536.44 | I16: =SUM(I7:I15) -> -326536.44

Sheet 📅 Jul
B2: July — Monthly Burn Entry (M5)
B3: Blue = enter data | Gray = formula | Green = cross-sheet link. Sub Actuals col locked for non-sub CLINs.
B4: 🟢 CPFF CLINs 1006/1007/1008 — Forecast auto-calculated from 💼 Labor Forecast tab. | FFP/ODC CLINs 1005/1009/1010/1016/1017/1018 — enter Forecast directly in blue cells.
B6: CLIN | C6: Description | D6: Type | E6: Prime Actuals ($) | F6: Sub Actuals ($) | G6: Total Actuals ($) | H6: Forecast ($) | I6: Variance ($) | J6: Notes
B7: ='⚙️ Setup'!B15 -> 1005 | C7: ='⚙️ Setup'!C15 -> Project Management | D7: ='⚙️ Setup'!D15 -> FFP | F7: 0 | G7: =IFERROR(E7,0)+IFERROR(F7,0) -> 0 | H7: 48798.69 | I7: =G7-H7 -> -48798.69
B8: ='⚙️ Setup'!B16 -> 1006 | C8: ='⚙️ Setup'!C16 -> Software Maintenance | D8: ='⚙️ Setup'!D16 -> CPFF | F8: 0 | G8: =IFERROR(E8,0)+IFERROR(F8,0) -> 0 | H8: ='💼 Labor Forecast'!Q17 -> 107020.94 | I8: =G8-H8 -> -107020.94
B9: ='⚙️ Setup'!B17 -> 1007 | C9: ='⚙️ Setup'!C17 -> Software Development | D9: ='⚙️ Setup'!D17 -> CPFF | F9: 0 | G9: =IFERROR(E9,0)+IFERROR(F9,0) -> 0 | H9: ='💼 Labor Forecast'!Q30 -> 107020.94 | I9: =G9-H9 -> -107020.94
B10: ='⚙️ Setup'!B18 -> 1008 | C10: ='⚙️ Setup'!C18 -> O&M | D10: ='⚙️ Setup'!D18 -> CPFF | F10: 0 | G10: =IFERROR(E10,0)+IFERROR(F10,0) -> 0 | H10: ='💼 Labor Forecast'!Q38 -> 25477.891 | I10: =G10-H10 -> -25477.891
B11: ='⚙️ Setup'!B19 -> 1009 | C11: ='⚙️ Setup'!C19 -> Tier 3 Helpdesk | D11: ='⚙️ Setup'!D19 -> FFP | F11: 0 | G11: =IFERROR(E11,0)+IFERROR(F11,0) -> 0 | H11: 2775.82 | I11: =G11-H11 -> -2775.82
B12: ='⚙️ Setup'!B20 -> 1010 | C12: ='⚙️ Setup'!C20 -> Training | D12: ='⚙️ Setup'!D20 -> FFP | F12: 0 | G12: =IFERROR(E12,0)+IFERROR(F12,0) -> 0 | H12: 16374.71 | I12: =G12-H12 -> -16374.71
B13: ='⚙️ Setup'!B21 -> 1016 | C13: ='⚙️ Setup'!C21 -> NTIA | D13: ='⚙️ Setup'!D21 -> FFP | F13: 0 | G13: =IFERROR(E13,0)+IFERROR(F13,0) -> 0 | H13: 22067.34 | I13: =G13-H13 -> -22067.34
B14: ='⚙️ Setup'!B22 -> 1017 | C14: ='⚙️ Setup'!C22 -> Other Direct Costs | D14: ='⚙️ Setup'!D22 -> COST | F14: 0 | G14: =IFERROR(E14,0)+IFERROR(F14,0) -> 0 | H14: 7000 | I14: =G14-H14 -> -7000
B15: ='⚙️ Setup'!B23 -> 1018 | C15: ='⚙️ Setup'!C23 -> Travel | D15: ='⚙️ Setup'!D23 -> COST | F15: 0 | G15: =IFERROR(E15,0)+IFERROR(F15,0) -> 0 | H15: 0 | I15: =G15-H15 -> 0
B16: TOTAL | E16: =SUM(E7:E15) -> 0 | F16: =SUM(F7:F15) -> 0 | G16: =SUM(G7:G15) -> 0 | H16: =SUM(H7:H15) -> 336536.32 | I16: =SUM(I7:I15) -> -336536.32

Sheet 📅 Aug
B2: August — Monthly Burn Entry (M6)
B3: Blue = enter data | Gray = formula | Green = cross-sheet link. Sub Actuals col locked for non-sub CLINs.
B4: 🟢 CPFF CLINs 1006/1007/1008 — Forecast auto-calculated from 💼 Labor Forecast tab. | FFP/ODC CLINs 1005/1009/1010/1016/1017/1018 — enter Forecast directly in blue cells.
B6: CLIN | C6: Description | D6: Type | E6: Prime Actuals ($) | F6: Sub Actuals ($) | G6: Total Actuals ($) | H6: Forecast ($) | I6: Variance ($) | J6: Notes
B7: ='⚙️ Setup'!B15 -> 1005 | C7: ='⚙️ Setup'!C15 -> Project Management | D7: ='⚙️ Setup'!D15 -> FFP | F7: 0 | G7: =IFERROR(E7,0)+IFERROR(F7,0) -> 0 | H7: 50425.31 | I7: =G7-H7 -> -50425.31
B8: ='⚙️ Setup'!B16 -> 1006 | C8: ='⚙️ Setup'!C16 -> Software Maintenance | D8: ='⚙️ Setup'!D16 -> CPFF | F8: 0 | G8: =IFERROR(E8,0)+IFERROR(F8,0) -> 0 | H8: ='💼 Labor Forecast'!S17 -> 99582.394 | I8: =G8-H8 -> -99582.394
B9: ='⚙️ Setup'!B17 -> 1007 | C9: ='⚙️ Setup'!C17 -> Software Development | D9: ='⚙️ Setup'!D17 -> CPFF | F9: 0 | G9: =IFERROR(E9,0)+IFERROR(F9,0) -> 0 | H9: ='💼 Labor Forecast'!S30 -> 99582.394 | I9: =G9-H9 -> -99582.394
B10: ='⚙️ Setup'!B18 -> 1008 | C10: ='⚙️ Setup'!C18 -> O&M | D10: ='⚙️ Setup'!D18 -> CPFF | F10: 0 | G10: =IFERROR(E10,0)+IFERROR(F10,0) -> 0 | H10: ='💼 Labor Forecast'!S38 -> 23262.422 | I10: =G10-H10 -> -23262.422
B11: ='⚙️ Setup'!B19 -> 1009 | C11: ='⚙️ Setup'!C19 -> Tier 3 Helpdesk | D11: ='⚙️ Setup'!D19 -> FFP | F11: 0 | G11: =IFERROR(E11,0)+IFERROR(F11,0) -> 0 | H11: 2868.35 | I11: =G11-H11 -> -2868.35
B12: ='⚙️ Setup'!B20 -> 1010 | C12: ='⚙️ Setup'!C20 -> Training | D12: ='⚙️ Setup'!D20 -> FFP | F12: 0 | G12: =IFERROR(E12,0)+IFERROR(F12,0) -> 0 | H12: 16920.53 | I12: =G12-H12 -> -16920.53
B13: ='⚙️ Setup'!B21 -> 1016 | C13: ='⚙️ Setup'!C21 -> NTIA | D13: ='⚙️ Setup'!D21 -> FFP | F13: 0 | G13: =IFERROR(E13,0)+IFERROR(F13,0) -> 0 | H13: 22802.92 | I13: =G13-H13 -> -22802.92
B14: ='⚙️ Setup'!B22 -> 1017 | C14: ='⚙️ Setup'!C22 -> Other Direct Costs | D14: ='⚙️ Setup'!D22 -> COST | F14: 0 | G14: =IFERROR(E14,0)+IFERROR(F14,0) -> 0 | H14: 7000 | I14: =G14-H14 -> -7000
B15: ='⚙️ Setup'!B23 -> 1018 | C15: ='⚙️ Setup'!C23 -> Travel | D15: ='⚙️ Setup'!D23 -> COST | F15: 0 | G15: =IFERROR(E15,0)+IFERROR(F15,0) -> 0 | H15: 0 | I15: =G15-H15 -> 0
B16: TOTAL | E16: =SUM(E7:E15) -> 0 | F16: =SUM(F7:F15) -> 0 | G16: =SUM(G7:G15) -> 0 | H16: =SUM(H7:H15) -> 322444.32 | I16: =SUM(I7:I15) -> -322444.32

Sheet 📅 Sep
B2: September — Monthly Burn Entry (M7)
B3: Blue = enter data | Gray = formula | Green = cross-sheet link. Sub Actuals col locked for non-sub CLINs.
B4: 🟢 CPFF CLINs 1006/1007/1008 — Forecast auto-calculated from 💼 Labor Forecast tab. | FFP/ODC CLINs 1005/1009/1010/1016/1017/1018 — enter Forecast directly in blue cells.
B6: CLIN | C6: Description | D6: Type | E6: Prime Actuals ($) | F6: Sub Actuals ($) | G6: Total Actuals ($) | H6: Forecast ($) | I6: Variance ($) | J6: Notes
